Workbook

Sheet Overall_Summary_Q1_Data
A3: Q1-2025 - Total Electric Line Extension Applications
A4: Type of Construction | B4: Customer Class | C4: Mixed Fuel | D4: All-Electric | E4: Total | F4: Percent All-Electric
A5: PG&E
A6: Upgrade | B6: Residential | C6: =C36 -> 5 | D6: =D36 -> 132 | E6: =E36 -> 137 | F6: =F36 -> 0.96350365 | H6: QC Check
A7: Upgrade | B7: Commercial | C7: =C37 -> 1 | D7: =D37 -> 37 | E7: =E37 -> 38 | F7: =F37 -> 0.97368421 | H7: Iou | K7: Calculated Percent AE | L7: Tableau Percent AE
A8: New Construction | B8: Agency (City, County, Caltrans) | C8: =C43 -> 4 | D8: =D43 -> 226 | E8: =E43 -> 230 | F8: =F43 -> 0.9826087 | H8: PGE | I8: AE Total Apps | J8: =SUM(D36:D50) -> 4460 | K8: =J8/J9 -> 0.79928315 | L8: 0.81
A9: New Construction | B9: Industrial | C9: =C44 -> 8 | D9: =D44 -> 75 | E9: =E44 -> 83 | F9: =F44 -> 0.90361446 | I9: Total ELE Apps | J9: =SUM(E36:E50) -> 5580
A10: New Construction | B10: Mixed Use (Commercial / Residential) | C10: =C45 -> 44 | D10: =D45 -> 82 | E10: =E45 -> 126 | F10: =F45 -> 0.65079365 | H10: SDGE | I10: AE Total Apps | J10: =SUM(D57:D64) -> 4338 | K10: =J10/J11 -> 0.75364837 | L10: 0.75
A11: New Construction | B11: Commercial | C11: =C46 -> 172 | D11: =D46 -> 669 | E11: =E46 -> 841 | F11: =F46 -> 0.79548157 | I11: Total ELE Apps | J11: =SUM(E57:E64) -> 5756
A12: New Construction | B12: Residential | C12: =C47 -> 886 | D12: =D47 -> 2445 | E12: =E47 -> 3331 | F12: =F47 -> 0.73401381 | H12: SCE | I12: AE Total Apps | J12: =SUM(D72:D77) -> 1550 | K12: =J12/J13 -> 0.2886406 | L12: 0.29
A13: SDGE | I13: Total ELE Apps | J13: =SUM(E72:E77) -> 5370
A14: Upgrade | B14: Commerical | C14: =C57 -> 62 | D14: =D57 -> 2515 | E14: =E57 -> 2577 | F14: =F57 -> 0.97594102
A15: Upgrade | B15: Residential | C15: =C58 -> 605 | D15: =D58 -> 257 | E15: =E58 -> 862 | F15: =F58 -> 0.29814385
A16: New Construction | B16: Commerical | C16: =C61 -> 167 | D16: =D61 -> 498 | E16: =E61 -> 665 | F16: =F61 -> 0.74887218
A17: New Construction | B17: Residential | C17: =C62 -> 584 | D17: =D62 -> 1063 | E17: =E62 -> 1647 | F17: =F62 -> 0.64541591
A18: SCE
A19: Upgrade | B19: Residential | C19: =C72 -> 2327 | D19: =D72 -> 95 | E19: =E72 -> 2422 | F19: =F72 -> 0.039223782
A20: Upgrade | B20: Commerical/Industrial | C20: =C73 -> 203 | D20: =D73 -> 72 | E20: =E73 -> 275 | F20: =F73 -> 0.26181818
A21: Upgrade | B21: Agriculture | C21: =C74 -> 5 | D21: =D74 -> 24 | E21: =E74 -> 29 | F21: =F74 -> 0.82758621
A22: New Construction | B22: Residential | C22: =C75 -> 911 | D22: =D75 -> 867 | E22: =E75 -> 1778 | F22: =F75 -> 0.48762655
A23: New Construction | B23: Commerical/Industrial | C23: =C76 -> 363 | D23: =D76 -> 473 | E23: =E76 -> 836 | F23: =F76 -> 0.56578947
A24: New Construction | B24: Agriculture | C24: =C77 -> 11 | D24: =D77 -> 19 | E24: =E77 -> 30 | F24: =F77 -> 0.63333333
A32: PG&E
A33: Total Electric Line Extension Applications
A35: Type of Construction | B35: Customer Class | C35: Mixed Fuel | D35: All-Electric | E35: Total | F35: Percent All-Electric
A36: Upgrade | B36: Residential | C36: =PGE_Q1_2025!Q10+PGE_Q1_2025!Q62+PGE_Q1_2025!R10+PGE_Q1_2025!R62 -> 5 | D36: =PGE_Q1_2025!Q86+PGE_Q1_2025!Q87+PGE_Q1_2025!Q95+PGE_Q1_2025!R86+PGE_Q1_2025!R87+PGE_Q1_2025!R95 -> 132 | E36: =C36+D36 -> 137 | F36: =D36/E36 -> 0.96350365
A37: Upgrade | B37: Commercial | C37: =PGE_Q1_2025!Q19+PGE_Q1_2025!R19 -> 1 | D37: =PGE_Q1_2025!Q34+PGE_Q1_2025!Q44+PGE_Q1_2025!Q53+PGE_Q1_2025!R34+PGE_Q1_2025!R44+PGE_Q1_2025!R53 -> 37 | E37: =C37+D37 -> 38 | F37: =D37/E37 -> 0.97368421
A38: Upgrade | B38: Agency (City, County, Caltrans) | D38: =PGE_Q1_2025!Q42+PGE_Q1_2025!Q67+PGE_Q1_2025!R42+PGE_Q1_2025!R67 -> 3 | E38: =C38+D38 -> 3 | F38: =D38/E38 -> 1
A39: Upgrade | B39: Agricultural | D39: =PGE_Q1_2025!Q43+PGE_Q1_2025!Q63+PGE_Q1_2025!R43+PGE_Q1_2025!R63 -> 5 | E39: =C39+D39 -> 5 | F39: =D39/E39 -> 1
A40: Upgrade | B40: Mixed Use (Commercial / Residential) | D40: =PGE_Q1_2025!Q64+PGE_Q1_2025!Q65+PGE_Q1_2025!Q73+PGE_Q1_2025!R64+PGE_Q1_2025!R65+PGE_Q1_2025!R73 -> 36 | E40: =C40+D40 -> 36 | F40: =D40/E40 -> 1
A41: Upgrade | B41: Telecommunications | D41: =PGE_Q1_2025!Q66+PGE_Q1_2025!Q72+PGE_Q1_2025!Q74+PGE_Q1_2025!R66+PGE_Q1_2025!R72+PGE_Q1_2025!R74 -> 65 | E41: =C41+D41 -> 65 | F41: =D41/E41 -> 1
A42: Upgrade | B42: Street and Outdoor area Lighting | D42: =PGE_Q1_2025!Q78+PGE_Q1_2025!R78 -> 7 | E42: =C42+D42 -> 7 | F42: =D42/E42 -> 1
A43: New Construction | B43: Agency (City, County, Caltrans) | C43: =PGE_Q1_2025!Q56+PGE_Q1_2025!Q57+PGE_Q1_2025!Q68+PGE_Q1_2025!R56+PGE_Q1_2025!R57+PGE_Q1_2025!R68 -> 4 | D43: =PGE_Q1_2025!Q89+PGE_Q1_2025!Q99+PGE_Q1_2025!Q100+PGE_Q1_2025!R89+PGE_Q1_2025!R99+PGE_Q1_2025!R100 -> 226 | E43: =C43+D43 -> 230 | F43: =D43/E43 -> 0.9826087
A44: New Construction | B44: Industrial | C44: =PGE_Q1_2025!Q58+PGE_Q1_2025!Q69+PGE_Q1_2025!Q71+PGE_Q1_2025!R58+PGE_Q1_2025!R69+PGE_Q1_2025!R71 -> 8 | D44: =PGE_Q1_2025!Q77+PGE_Q1_2025!Q81+PGE_Q1_2025!Q82+PGE_Q1_2025!R77+PGE_Q1_2025!R81+PGE_Q1_2025!R82 -> 75 | E44: =C44+D44 -> 83 | F44: =D44/E44 -> 0.90361446
A45: New Construction | B45: Mixed Use (Commercial / Residential) | C45: =PGE_Q1_2025!Q70+PGE_Q1_2025!Q75+PGE_Q1_2025!Q79+PGE_Q1_2025!Q70+PGE_Q1_2025!Q75+PGE_Q1_2025!Q79+PGE_Q1_2025!R70+PGE_Q1_2025!R75+PGE_Q1_2025!R79+PGE_Q1_2025!R70+PGE_Q1_2025!R75+PGE_Q1_2025!R79 -> 44 | D45: =PGE_Q1_2025!Q80+PGE_Q1_2025!Q83+PGE_Q1_2025!Q85+PGE_Q1_2025!R80+PGE_Q1_2025!R83+PGE_Q1_2025!R85 -> 82 | E45: =C45+D45 -> 126 | F45: =D45/E45 -> 0.65079365
A46: New Construction | B46: Commercial | C46: =PGE_Q1_2025!Q88+PGE_Q1_2025!Q90+PGE_Q1_2025!Q101+PGE_Q1_2025!Q88+PGE_Q1_2025!Q90+PGE_Q1_2025!Q101 -> 172 | D46: =PGE_Q1_2025!Q102+PGE_Q1_2025!Q104+PGE_Q1_2025!Q105+PGE_Q1_2025!R102+PGE_Q1_2025!R104+PGE_Q1_2025!R105 -> 669 | E46: =C46+D46 -> 841 | F46: =D46/E46 -> 0.79548157
A47: New Construction | B47: Residential | C47: =PGE_Q1_2025!Q103+PGE_Q1_2025!Q107+PGE_Q1_2025!Q106+PGE_Q1_2025!R103+PGE_Q1_2025!R107+PGE_Q1_2025!R106 -> 886 | D47: =PGE_Q1_2025!Q108+PGE_Q1_2025!Q109+PGE_Q1_2025!Q110+PGE_Q1_2025!R108+PGE_Q1_2025!R109+PGE_Q1_2025!R110 -> 2445 | E47: =C47+D47 -> 3331 | F47: =D47/E47 -> 0.73401381
A48: New Construction | B48: Agricultural | D48: =PGE_Q1_2025!Q91+PGE_Q1_2025!Q93+PGE_Q1_2025!Q97+PGE_Q1_2025!R91+PGE_Q1_2025!R93+PGE_Q1_2025!R97 -> 300 | E48: =C48+D48 -> 300 | F48: =D48/E48 -> 1
A49: New Construction | B49: Street and Outdoor area Lighting | D49: =PGE_Q1_2025!Q76+PGE_Q1_2025!Q84+PGE_Q1_2025!Q98+PGE_Q1_2025!R76+PGE_Q1_2025!R84+PGE_Q1_2025!R98 -> 70 | E49: =C49+D49 -> 70 | F49: =D49/E49 -> 1
A50: New Construction | B50: Telecommunications | D50: =PGE_Q1_2025!Q92+PGE_Q1_2025!Q94+PGE_Q1_2025!Q96+PGE_Q1_2025!R92+PGE_Q1_2025!R94+PGE_Q1_2025!R96 -> 308 | E50: =C50+D50 -> 308 | F50: =D50/E50 -> 1
...

Sheet Summary_Q1_Data_IOU
A3: Q1-2025 - Total Electric Line Extension Applications (IOU Installed)
A4: Type of Construction | B4: Customer Class | C4: Mixed Fuel | D4: All-Electric | E4: Total | F4: Percent All-Electric
A5: PG&E
A6: Upgrade | B6: Residential | C6: =C36 -> 4 | D6: =D36 -> 102 | E6: =E36 -> 106 | F6: =F36 -> 0.96226415
A7: Upgrade | B7: Commercial | C7: =C37 -> 1 | D7: =D37 -> 37 | E7: =E37 -> 38 | F7: =F37 -> 0.97368421
A8: New Construction | B8: Agency (City, County, Caltrans) | C8: =C43 -> 3 | D8: =D43 -> 182 | E8: =E43 -> 185 | F8: =F43 -> 0.98378378
A9: New Construction | B9: Industrial | C9: =C44 -> 6 | D9: =D44 -> 64 | E9: =E44 -> 70 | F9: =F44 -> 0.91428571
A10: New Construction | B10: Mixed Use (Commercial / Residential) | C10: =C45 -> 15 | D10: =D45 -> 66 | E10: =E45 -> 81 | F10: =F45 -> 0.81481481
A11: New Construction | B11: Commercial | C11: =C46 -> 86 | D11: =D46 -> 526 | E11: =E46 -> 612 | F11: =F46 -> 0.85947712
A12: New Construction | B12: Residential | C12: =C47 -> 722 | D12: =D47 -> 1951 | E12: =E47 -> 2673 | F12: =F47 -> 0.72989151
A13: SDGE
A14: Upgrade | B14: Commerical | C14: =C57 -> 62 | D14: =D57 -> 2515 | E14: =E57 -> 2577 | F14: =F57 -> 0.97594102
A15: Upgrade | B15: Residential | C15: =C58 -> 605 | D15: =D58 -> 257 | E15: =E58 -> 862 | F15: =F58 -> 0.29814385
A16: New Construction | B16: Commerical | C16: =C61 -> 167 | D16: =D61 -> 498 | E16: =E61 -> 665 | F16: =F61 -> 0.74887218
A17: New Construction | B17: Residential | C17: =C62 -> 583 | D17: =D62 -> 1063 | E17: =E62 -> 1646 | F17: =F62 -> 0.64580802
A18: SCE
A19: Upgrade | B19: Residential | C19: =C72 -> 2326 | D19: =D72 -> 95 | E19: =E72 -> 2421 | F19: =F72 -> 0.039239983
A20: Upgrade | B20: Commerical/Industrial | C20: =C73 -> 203 | D20: =D73 -> 71 | E20: =E73 -> 274 | F20: =F73 -> 0.25912409
A21: Upgrade | B21: Agriculture | C21: =C74 -> 5 | D21: =D74 -> 24 | E21: =E74 -> 29 | F21: =F74 -> 0.82758621
A22: New Construction | B22: Residential | C22: =C75 -> 911 | D22: =D75 -> 788 | E22: =E75 -> 1699 | F22: =F75 -> 0.46380224
A23: New Construction | B23: Commerical/Industrial | C23: =C76 -> 363 | D23: =D76 -> 463 | E23: =E76 -> 826 | F23: =F76 -> 0.56053269
A24: New Construction | B24: Agriculture | C24: =C77 -> 11 | D24: =D77 -> 19 | E24: =E77 -> 30 | F24: =F77 -> 0.63333333
A32: PG&E
A33: Total Electric Line Extension Applications (IOU Installed)
A35: Type of Construction | B35: Customer Class | C35: Mixed Fuel | D35: All-Electric | E35: Total | F35: Percent All-Electric
A36: Upgrade | B36: Residential | C36: =PGE_Q1_2025!Q10+PGE_Q1_2025!Q62 -> 4 | D36: =PGE_Q1_2025!Q86+PGE_Q1_2025!Q87+PGE_Q1_2025!Q95 -> 102 | E36: =C36+D36 -> 106 | F36: =D36/E36 -> 0.96226415
A37: Upgrade | B37: Commercial | C37: =PGE_Q1_2025!Q19 -> 1 | D37: =PGE_Q1_2025!Q34+PGE_Q1_2025!Q44+PGE_Q1_2025!Q53 -> 37 | E37: =C37+D37 -> 38 | F37: =D37/E37 -> 0.97368421
A38: Upgrade | B38: Agency (City, County, Caltrans) | D38: =PGE_Q1_2025!Q42+PGE_Q1_2025!Q67 -> 2 | E38: =C38+D38 -> 2 | F38: =D38/E38 -> 1
A39: Upgrade | B39: Agricultural | D39: =PGE_Q1_2025!Q43+PGE_Q1_2025!Q63 -> 4 | E39: =C39+D39 -> 4 | F39: =D39/E39 -> 1
A40: Upgrade | B40: Mixed Use (Commercial / Residential) | D40: =PGE_Q1_2025!Q64+PGE_Q1_2025!Q65+PGE_Q1_2025!Q73 -> 32 | E40: =C40+D40 -> 32 | F40: =D40/E40 -> 1
A41: Upgrade | B41: Telecommunications | D41: =PGE_Q1_2025!Q66+PGE_Q1_2025!Q72+PGE_Q1_2025!Q74 -> 60 | E41: =C41+D41 -> 60 | F41: =D41/E41 -> 1
A42: Upgrade | B42: Street and Outdoor area Lighting | D42: =PGE_Q1_2025!Q78 -> 4 | E42: =C42+D42 -> 4 | F42: =D42/E42 -> 1
A43: New Construction | B43: Agency (City, County, Caltrans) | C43: =PGE_Q1_2025!Q56+PGE_Q1_2025!Q57+PGE_Q1_2025!Q68 -> 3 | D43: =PGE_Q1_2025!Q89+PGE_Q1_2025!Q99+PGE_Q1_2025!Q100 -> 182 | E43: =C43+D43 -> 185 | F43: =D43/E43 -> 0.98378378
A44: New Construction | B44: Industrial | C44: =PGE_Q1_2025!Q58+PGE_Q1_2025!Q69+PGE_Q1_2025!Q71 -> 6 | D44: =PGE_Q1_2025!Q77+PGE_Q1_2025!Q81+PGE_Q1_2025!Q82 -> 64 | E44: =C44+D44 -> 70 | F44: =D44/E44 -> 0.91428571
A45: New Construction | B45: Mixed Use (Commercial / Residential) | C45: =PGE_Q1_2025!Q70+PGE_Q1_2025!Q75+PGE_Q1_2025!Q79 -> 15 | D45: =PGE_Q1_2025!Q80+PGE_Q1_2025!Q83+PGE_Q1_2025!Q85 -> 66 | E45: =C45+D45 -> 81 | F45: =D45/E45 -> 0.81481481
A46: New Construction | B46: Commercial | C46: =PGE_Q1_2025!Q88+PGE_Q1_2025!Q90+PGE_Q1_2025!Q101 -> 86 | D46: =PGE_Q1_2025!Q102+PGE_Q1_2025!Q104+PGE_Q1_2025!Q105 -> 526 | E46: =C46+D46 -> 612 | F46: =D46/E46 -> 0.85947712
A47: New Construction | B47: Residential | C47: =PGE_Q1_2025!Q103+PGE_Q1_2025!Q107+PGE_Q1_2025!Q106 -> 722 | D47: =PGE_Q1_2025!Q108+PGE_Q1_2025!Q109+PGE_Q1_2025!Q110 -> 1951 | E47: =C47+D47 -> 2673 | F47: =D47/E47 -> 0.72989151
A48: New Construction | B48: Agricultural | D48: =PGE_Q1_2025!Q91+PGE_Q1_2025!Q93+PGE_Q1_2025!Q97 -> 259 | E48: =C48+D48 -> 259 | F48: =D48/E48 -> 1
A49: New Construction | B49: Street and Outdoor area Lighting | D49: =PGE_Q1_2025!Q76+PGE_Q1_2025!Q84+PGE_Q1_2025!Q98 -> 46 | E49: =C49+D49 -> 46 | F49: =D49/E49 -> 1
A50: New Construction | B50: Telecommunications | D50: =PGE_Q1_2025!Q92+PGE_Q1_2025!Q94+PGE_Q1_2025!Q96 -> 267 | E50: =C50+D50 -> 267 | F50: =D50/E50 -> 1
...

Sheet Combination
A1: New Construction / Upgrade | B1: Mixed Fuel / All Electric | C1: Months | D1: Customer Class | E1: Baseline / Climate Zone | F1: Multi Dwelling | G1: Total Discounts (Non-Exempted Projects) | H1: Total Allowances (Non-Exempted Projects) | I1: Total Refund Payments Provided to Builders (Non-Exempted Projects) | J1: Total Discounts (Exempted projects) | K1: Total Allowances (Exempted projects) | L1: Total Refund Payments Provided to Builders (Exempted projects) | M1: Total Estimated Non-Refundable | N1: Total Estimated Refundable | O1: Average Number of days between full payment and Project Energization | P1: Total Electric Line Extensions Energized | Q1: Total Electric Line Extension Applications (IOU Installed) | R1: Total Electric Line Extension Applications (Applicant Installed) | S1: IoU | T1: Year
A2: Upgrade | B2: Mixed Fuel | C2: 45689 | D2: Unknown | E2: Unknown | F2: Unknown | G2: 0 | H2: 8533.94 | J2: 0 | K2: 0 | M2: 5383.0484 | N2: 9919.08 | P2: 1 | S2: PG&E | T2: 2025
A3: Upgrade | B3: Mixed Fuel | C3: 45689 | D3: Unknown | E3: Unknown | F3: Unknown | P3: 1 | S3: PG&E | T3: 2025
A4: Upgrade | B4: Mixed Fuel | C4: 45689 | D4: Unknown | E4: Unknown | F4: Unknown | P4: 1 | S4: PG&E | T4: 2025
A5: Upgrade | B5: Mixed Fuel | C5: 45689 | D5: Agency (City, County, Caltrans) | E5: Unknown | F5: Nonresidential | P5: 1 | S5: PG&E | T5: 2025
A6: Upgrade | B6: Mixed Fuel | C6: 45689 | D6: Agriculture | E6: Unknown | F6: Nonresidential | P6: 1 | S6: PG&E | T6: 2025
A7: Upgrade | B7: Mixed Fuel | C7: 45689 | D7: Commercial | E7: Unknown | F7: Nonresidential | P7: 2 | S7: PG&E | T7: 2025
A8: Upgrade | B8: Mixed Fuel | C8: 45689 | D8: Industrial | E8: Unknown | F8: Nonresidential | P8: 1 | S8: PG&E | T8: 2025
A9: Upgrade | B9: Mixed Fuel | C9: 45689 | D9: Mixed Use (Commercial / Residential) | E9: Unknown | F9: Unknown | P9: 1 | S9: PG&E | T9: 2025
A10: Upgrade | B10: Mixed Fuel | C10: 45689 | D10: Residential | E10: Unknown | F10: Unknown | G10: 31937 | H10: 156343.53 | J10: 0 | K10: 0 | M10: 111666.35 | N10: 255414.29 | P10: 11 | Q10: 1 | S10: PG&E | T10: 2025
A11: Upgrade | B11: Mixed Fuel | C11: 45689 | D11: Street and Outdoor area Lighting | E11: Unknown | F11: Nonresidential | P11: 1 | S11: PG&E | T11: 2025
A12: Upgrade | B12: Mixed Fuel | C12: 45689 | D12: Telecommunications | E12: Unknown | F12: Nonresidential | P12: 1 | S12: PG&E | T12: 2025
A13: Upgrade | B13: Mixed Fuel | C13: 45689 | D13: Temporary Services | E13: Unknown | F13: Nonresidential | P13: 1 | S13: PG&E | T13: 2025
A14: Upgrade | B14: Mixed Fuel | C14: 45658 | D14: Unknown | E14: Unknown | F14: Unknown | G14: 0 | H14: 5522.82 | J14: 0 | K14: 0 | M14: 953.956 | N14: 5522.82 | P14: 1 | S14: PG&E | T14: 2025
A15: Upgrade | B15: Mixed Fuel | C15: 45658 | D15: Unknown | E15: Unknown | F15: Unknown | P15: 1 | S15: PG&E | T15: 2025
A16: Upgrade | B16: Mixed Fuel | C16: 45658 | D16: Unknown | E16: Unknown | F16: Unknown | P16: 1 | S16: PG&E | T16: 2025
A17: Upgrade | B17: Mixed Fuel | C17: 45658 | D17: Agency (City, County, Caltrans) | E17: Unknown | F17: Nonresidential | G17: 8548.8476 | H17: 2130.1789 | J17: 0 | K17: 0 | M17: 1691.9108 | N17: 19227.874 | P17: 1 | S17: PG&E | T17: 2025
A18: Upgrade | B18: Mixed Fuel | C18: 45658 | D18: Agriculture | E18: Unknown | F18: Nonresidential | P18: 1 | S18: PG&E | T18: 2025
A19: Upgrade | B19: Mixed Fuel | C19: 45658 | D19: Commercial | E19: Unknown | F19: Nonresidential | G19: 64648.527 | H19: 7515.3577 | J19: 0 | K19: 0 | M19: 18569.465 | N19: 137089.74 | P19: 3 | Q19: 1 | S19: PG&E | T19: 2025
A20: Upgrade | B20: Mixed Fuel | C20: 45658 | D20: Industrial | E20: Unknown | F20: Nonresidential | P20: 1 | S20: PG&E | T20: 2025
A21: Upgrade | B21: Mixed Fuel | C21: 45658 | D21: Mixed Use (Commercial / Residential) | E21: Unknown | F21: Unknown | P21: 1 | S21: PG&E | T21: 2025
A22: Upgrade | B22: Mixed Fuel | C22: 45658 | D22: Street and Outdoor area Lighting | E22: Unknown | F22: Nonresidential | P22: 1 | S22: PG&E | T22: 2025
A23: Upgrade | B23: Mixed Fuel | C23: 45658 | D23: Telecommunications | E23: Unknown | F23: Nonresidential | P23: 1 | S23: PG&E | T23: 2025
A24: Upgrade | B24: Mixed Fuel | C24: 45658 | D24: Temporary Services | E24: Unknown | F24: Nonresidential | P24: 1 | S24: PG&E | T24: 2025
A25: Upgrade | B25: Mixed Fuel | C25: 45717 | D25: Unknown | E25: Unknown | F25: Unknown | G25: 0 | H25: 3255 | J25: 0 | K25: 0 | M25: 4425.1204 | N25: 4896.79 | P25: 1 | S25: PG&E | T25: 2025
A26: Upgrade | B26: Mixed Fuel | C26: 45717 | D26: Agency (City, County, Caltrans) | E26: Unknown | F26: Nonresidential | G26: 31766.718 | H26: 42005.42 | J26: 0 | K26: 0 | M26: 15494.13 | N26: 105538.86 | P26: 1 | S26: PG&E | T26: 2025
A27: Upgrade | B27: Mixed Fuel | C27: 45717 | D27: Commercial | E27: Unknown | F27: Nonresidential | G27: 49847.814 | H27: 0 | J27: 0 | K27: 0 | M27: 5566.1264 | N27: 99695.628 | P27: 3 | S27: PG&E | T27: 2025
A28: Upgrade | B28: Mixed Fuel | C28: 45717 | D28: Residential | E28: Unknown | F28: Unknown | G28: 11973.614 | H28: 67280.45 | J28: 0 | K28: 0 | M28: 154248.96 | N28: 154079.07 | P28: 26 | S28: PG&E | T28: 2025
A29: Upgrade | B29: All Electric | C29: 45689 | D29: Unknown | E29: Unknown | F29: Unknown | G29: 141856.94 | H29: 60385.841 | J29: 0 | K29: 0 | M29: 26727.868 | N29: 345389.64 | P29: 1 | S29: PG&E | T29: 2025
A30: Upgrade | B30: All Electric | C30: 45689 | D30: Unknown | E30: Unknown | F30: Unknown | I30: 32476.71 | L30: 0 | P30: 1 | S30: PG&E | T30: 2025
A31: Upgrade | B31: All Electric | C31: 45689 | D31: Unknown | E31: Unknown | F31: Unknown | P31: 1 | S31: PG&E | T31: 2025
A32: Upgrade | B32: All Electric | C32: 45689 | D32: Unknown | E32: Unknown | F32: Unknown | P32: 1 | S32: PG&E | T32: 2025
A33: Upgrade | B33: All Electric | C33: 45689 | D33: Agency (City, County, Caltrans) | E33: Unknown | F33: Nonresidential | G33: 19272.001 | H33: 5161.5828 | J33: 0 | K33: 0 | M33: 20241.556 | N33: 43705.586 | P33: 3 | S33: PG&E | T33: 2025
A34: Upgrade | B34: All Electric | C34: 45689 | D34: Commercial | E34: Unknown | F34: Nonresidential | G34: 176103.93 | H34: 361069.03 | I34: 110533.13 | J34: 0 | K34: 0 | L34: 0 | M34: 48973.906 | N34: 713276.88 | P34: 21 | Q34: 8 | S34: PG&E | T34: 2025
A35: Upgrade | B35: All Electric | C35: 45689 | D35: Industrial | E35: Unknown | F35: Nonresidential | G35: 65175.425 | H35: 198405.07 | J35: 0 | K35: 0 | M35: 10834.347 | N35: 328755.92 | P35: 2 | S35: PG&E | T35: 2025
A36: Upgrade | B36: All Electric | C36: 45689 | D36: Street and Outdoor area Lighting | E36: Unknown | F36: Nonresidential | J36: 0 | K36: 0 | M36: 71498.555 | P36: 1 | S36: PG&E | T36: 2025
A37: Upgrade | B37: All Electric | C37: 45689 | D37: Temporary Services | E37: Unknown | F37: Nonresidential | P37: 1 | S37: PG&E | T37: 2025
A38: Upgrade | B38: All Electric | C38: 45658 | D38: Unknown | E38: Unknown | F38: Unknown | G38: 27456.272 | H38: 72572.221 | J38: 0 | K38: 0 | M38: 24641.874 | N38: 127484.77 | P38: 1 | S38: PG&E | T38: 2025
A39: Upgrade | B39: All Electric | C39: 45658 | D39: Unknown | E39: Unknown | F39: Unknown | I39: 25433.44 | L39: 0 | P39: 1 | S39: PG&E | T39: 2025
A40: Upgrade | B40: All Electric | C40: 45658 | D40: Unknown | E40: Unknown | F40: Unknown | P40: 1 | S40: PG&E | T40: 2025
...

Sheet PGE_Q1_2025
A1: New Construction / Upgrade | B1: Mixed Fuel / All Electric | C1: Months | D1: Customer Class | E1: Baseline / Climate Zone | F1: Multi Dwelling | G1: Total Discounts (Non-Exempted Projects) | H1: Total Allowances (Non-Exempted Projects) | I1: Total Refund Payments Provided to Builders (Non-Exempted Projects) | J1: Total Discounts (Exempted projects) | K1: Total Allowances (Exempted projects) | L1: Total Refund Payments Provided to Builders (Exempted projects) | M1: Total Estimated Non-Refundable | N1: Total Estimated Refundable | O1: Average Number of days between full payment and Project Energization | P1: Total Electric Line Extensions Energized | Q1: Total Electric Line Extension Applications (IOU Installed) | R1: Total Electric Line Extension Applications (Applicant Installed) | S1: IoU | T1: Year
A2: Upgrade | B2: Mixed Fuel | C2: 45689 | D2: Unknown | E2: Unknown | F2: Unknown | G2: 0 | H2: 8533.94 | J2: 0 | K2: 0 | M2: 5383.0484 | N2: 9919.08 | P2: 1 | S2: PG&E | T2: =2025 -> 2025
A3: Upgrade | B3: Mixed Fuel | C3: 45689 | D3: Unknown | E3: Unknown | F3: Unknown | P3: 1 | S3: PG&E | T3: =2025 -> 2025
A4: Upgrade | B4: Mixed Fuel | C4: 45689 | D4: Unknown | E4: Unknown | F4: Unknown | P4: 1 | S4: PG&E | T4: =2025 -> 2025
A5: Upgrade | B5: Mixed Fuel | C5: 45689 | D5: Agency (City, County, Caltrans) | E5: Unknown | F5: Nonresidential | P5: 1 | S5: PG&E | T5: =2025 -> 2025
A6: Upgrade | B6: Mixed Fuel | C6: 45689 | D6: Agriculture | E6: Unknown | F6: Nonresidential | P6: 1 | S6: PG&E | T6: =2025 -> 2025
A7: Upgrade | B7: Mixed Fuel | C7: 45689 | D7: Commercial | E7: Unknown | F7: Nonresidential | P7: 2 | S7: PG&E | T7: =2025 -> 2025
A8: Upgrade | B8: Mixed Fuel | C8: 45689 | D8: Industrial | E8: Unknown | F8: Nonresidential | P8: 1 | S8: PG&E | T8: =2025 -> 2025
A9: Upgrade | B9: Mixed Fuel | C9: 45689 | D9: Mixed Use (Commercial / Residential) | E9: Unknown | F9: Unknown | P9: 1 | S9: PG&E | T9: =2025 -> 2025
A10: Upgrade | B10: Mixed Fuel | C10: 45689 | D10: Residential | E10: Unknown | F10: Unknown | G10: 31937 | H10: 156343.53 | J10: 0 | K10: 0 | M10: 111666.35 | N10: 255414.29 | P10: 11 | Q10: 1 | S10: PG&E | T10: =2025 -> 2025
A11: Upgrade | B11: Mixed Fuel | C11: 45689 | D11: Street and Outdoor area Lighting | E11: Unknown | F11: Nonresidential | P11: 1 | S11: PG&E | T11: =2025 -> 2025
A12: Upgrade | B12: Mixed Fuel | C12: 45689 | D12: Telecommunications | E12: Unknown | F12: Nonresidential | P12: 1 | S12: PG&E | T12: =2025 -> 2025
A13: Upgrade | B13: Mixed Fuel | C13: 45689 | D13: Temporary Services | E13: Unknown | F13: Nonresidential | P13: 1 | S13: PG&E | T13: =2025 -> 2025
A14: Upgrade | B14: Mixed Fuel | C14: 45658 | D14: Unknown | E14: Unknown | F14: Unknown | G14: 0 | H14: 5522.82 | J14: 0 | K14: 0 | M14: 953.956 | N14: 5522.82 | P14: 1 | S14: PG&E | T14: =2025 -> 2025
A15: Upgrade | B15: Mixed Fuel | C15: 45658 | D15: Unknown | E15: Unknown | F15: Unknown | P15: 1 | S15: PG&E | T15: =2025 -> 2025
A16: Upgrade | B16: Mixed Fuel | C16: 45658 | D16: Unknown | E16: Unknown | F16: Unknown | P16: 1 | S16: PG&E | T16: =2025 -> 2025
A17: Upgrade | B17: Mixed Fuel | C17: 45658 | D17: Agency (City, County, Caltrans) | E17: Unknown | F17: Nonresidential | G17: 8548.8476 | H17: 2130.1789 | J17: 0 | K17: 0 | M17: 1691.9108 | N17: 19227.874 | P17: 1 | S17: PG&E | T17: =2025 -> 2025
A18: Upgrade | B18: Mixed Fuel | C18: 45658 | D18: Agriculture | E18: Unknown | F18: Nonresidential | P18: 1 | S18: PG&E | T18: =2025 -> 2025
A19: Upgrade | B19: Mixed Fuel | C19: 45658 | D19: Commercial | E19: Unknown | F19: Nonresidential | G19: 64648.527 | H19: 7515.3577 | J19: 0 | K19: 0 | M19: 18569.465 | N19: 137089.74 | P19: 3 | Q19: 1 | S19: PG&E | T19: =2025 -> 2025
A20: Upgrade | B20: Mixed Fuel | C20: 45658 | D20: Industrial | E20: Unknown | F20: Nonresidential | P20: 1 | S20: PG&E | T20: =2025 -> 2025
A21: Upgrade | B21: Mixed Fuel | C21: 45658 | D21: Mixed Use (Commercial / Residential) | E21: Unknown | F21: Unknown | P21: 1 | S21: PG&E | T21: =2025 -> 2025
A22: Upgrade | B22: Mixed Fuel | C22: 45658 | D22: Street and Outdoor area Lighting | E22: Unknown | F22: Nonresidential | P22: 1 | S22: PG&E | T22: =2025 -> 2025
A23: Upgrade | B23: Mixed Fuel | C23: 45658 | D23: Telecommunications | E23: Unknown | F23: Nonresidential | P23: 1 | S23: PG&E | T23: =2025 -> 2025
A24: Upgrade | B24: Mixed Fuel | C24: 45658 | D24: Temporary Services | E24: Unknown | F24: Nonresidential | P24: 1 | S24: PG&E | T24: =2025 -> 2025
A25: Upgrade | B25: Mixed Fuel | C25: 45717 | D25: Unknown | E25: Unknown | F25: Unknown | G25: 0 | H25: 3255 | J25: 0 | K25: 0 | M25: 4425.1204 | N25: 4896.79 | P25: 1 | S25: PG&E | T25: =2025 -> 2025
A26: Upgrade | B26: Mixed Fuel | C26: 45717 | D26: Agency (City, County, Caltrans) | E26: Unknown | F26: Nonresidential | G26: 31766.718 | H26: 42005.42 | J26: 0 | K26: 0 | M26: 15494.13 | N26: 105538.86 | P26: 1 | S26: PG&E | T26: =2025 -> 2025
A27: Upgrade | B27: Mixed Fuel | C27: 45717 | D27: Commercial | E27: Unknown | F27: Nonresidential | G27: 49847.814 | H27: 0 | J27: 0 | K27: 0 | M27: 5566.1264 | N27: 99695.628 | P27: 3 | S27: PG&E | T27: =2025 -> 2025
A28: Upgrade | B28: Mixed Fuel | C28: 45717 | D28: Residential | E28: Unknown | F28: Unknown | G28: 11973.614 | H28: 67280.45 | J28: 0 | K28: 0 | M28: 154248.96 | N28: 154079.07 | P28: 26 | S28: PG&E | T28: =2025 -> 2025
A29: Upgrade | B29: All Electric | C29: 45689 | D29: Unknown | E29: Unknown | F29: Unknown | G29: 141856.94 | H29: 60385.841 | J29: 0 | K29: 0 | M29: 26727.868 | N29: 345389.64 | P29: 1 | S29: PG&E | T29: =2025 -> 2025
A30: Upgrade | B30: All Electric | C30: 45689 | D30: Unknown | E30: Unknown | F30: Unknown | I30: 32476.71 | L30: 0 | P30: 1 | S30: PG&E | T30: =2025 -> 2025
A31: Upgrade | B31: All Electric | C31: 45689 | D31: Unknown | E31: Unknown | F31: Unknown | P31: 1 | S31: PG&E | T31: =2025 -> 2025
A32: Upgrade | B32: All Electric | C32: 45689 | D32: Unknown | E32: Unknown | F32: Unknown | P32: 1 | S32: PG&E | T32: =2025 -> 2025
A33: Upgrade | B33: All Electric | C33: 45689 | D33: Agency (City, County, Caltrans) | E33: Unknown | F33: Nonresidential | G33: 19272.001 | H33: 5161.5828 | J33: 0 | K33: 0 | M33: 20241.556 | N33: 43705.586 | P33: 3 | S33: PG&E | T33: =2025 -> 2025
A34: Upgrade | B34: All Electric | C34: 45689 | D34: Commercial | E34: Unknown | F34: Nonresidential | G34: 176103.93 | H34: 361069.03 | I34: 110533.13 | J34: 0 | K34: 0 | L34: 0 | M34: 48973.906 | N34: 713276.88 | P34: 21 | Q34: 8 | S34: PG&E | T34: =2025 -> 2025
A35: Upgrade | B35: All Electric | C35: 45689 | D35: Industrial | E35: Unknown | F35: Nonresidential | G35: 65175.425 | H35: 198405.07 | J35: 0 | K35: 0 | M35: 10834.347 | N35: 328755.92 | P35: 2 | S35: PG&E | T35: =2025 -> 2025
A36: Upgrade | B36: All Electric | C36: 45689 | D36: Street and Outdoor area Lighting | E36: Unknown | F36: Nonresidential | J36: 0 | K36: 0 | M36: 71498.555 | P36: 1 | S36: PG&E | T36: =2025 -> 2025
A37: Upgrade | B37: All Electric | C37: 45689 | D37: Temporary Services | E37: Unknown | F37: Nonresidential | P37: 1 | S37: PG&E | T37: =2025 -> 2025
A38: Upgrade | B38: All Electric | C38: 45658 | D38: Unknown | E38: Unknown | F38: Unknown | G38: 27456.272 | H38: 72572.221 | J38: 0 | K38: 0 | M38: 24641.874 | N38: 127484.77 | P38: 1 | S38: PG&E | T38: =2025 -> 2025
A39: Upgrade | B39: All Electric | C39: 45658 | D39: Unknown | E39: Unknown | F39: Unknown | I39: 25433.44 | L39: 0 | P39: 1 | S39: PG&E | T39: =2025 -> 2025
A40: Upgrade | B40: All Electric | C40: 45658 | D40: Unknown | E40: Unknown | F40: Unknown | P40: 1 | S40: PG&E | T40: =2025 -> 2025
...

Sheet SCE_Q1_2025
A1: New Construction / Upgrade | B1: Mixed Fuel / All Electric | C1: Months | D1: Customer Class | E1: Baseline / Climate Zone | F1: Multi Dwelling | G1: Total Discounts (Non-Exempted Projects) | H1: Total Allowances (Non-Exempted Projects) | I1: Total Refund Payments Provided to Builders (Non-Exempted Projects) | J1: Total Discounts (Exempted projects) | K1: Total Allowances (Exempted projects) | L1: Total Refund Payments Provided to Builders (Exempted projects) | M1: Total Estimated Non-Refundable | N1: Total Estimated Refundable | O1: Average Number of days between full payment and Project Energization | P1: Total Electric Line Extensions Energized | Q1: Total Electric Line Extension Applications (IOU Installed) | R1: Total Electric Line Extension Applications (Applicant Installed) | S1: IoU | T1: Year
A2: New Construction | B2: All Electric | C2: 45658 | D2: Agriculture | E2: 6 | F2: Nonresidential | G2: 0 | H2: 4742.7 | I2: 0 | J2: 0 | K2: 0 | L2: 0 | M2: 0 | N2: 0 | O2: 217.6791 | P2: 1 | Q2: 0 | R2: 0 | S2: SCE | T2: =2025 -> 2025
A3: New Construction | B3: All Electric | C3: 45658 | D3: Agriculture | E3: 9 | F3: Nonresidential | G3: 0 | H3: 0 | I3: 0 | J3: 0 | K3: 0 | L3: 0 | M3: 0 | N3: 0 | O3: N/A | P3: 0 | Q3: 2 | R3: 0 | S3: SCE | T3: =2025 -> 2025
A4: New Construction | B4: All Electric | C4: 45658 | D4: Agriculture | E4: 13 | F4: Nonresidential | G4: 0 | H4: 77692.04 | I4: 0 | J4: 0 | K4: 0 | L4: 0 | M4: 0 | N4: 0 | O4: 213.49862 | P4: 2 | Q4: 2 | R4: 0 | S4: SCE | T4: =2025 -> 2025
A5: New Construction | B5: All Electric | C5: 45658 | D5: Agriculture | E5: 16 | F5: Nonresidential | G5: 0 | H5: 0 | I5: 0 | J5: 0 | K5: 0 | L5: 0 | M5: 0 | N5: 0 | O5: N/A | P5: 0 | Q5: 1 | R5: 0 | S5: SCE | T5: =2025 -> 2025
A6: New Construction | B6: All Electric | C6: 45658 | D6: Commercial / Industrial | E6: 6 | F6: Nonresidential | G6: 0 | H6: 164760.3 | I6: 31706.56 | J6: 0 | K6: 0 | L6: 0 | M6: 11145.22 | N6: 0 | O6: 54.565177 | P6: 4 | Q6: 30 | R6: 0 | S6: SCE | T6: =2025 -> 2025
A7: New Construction | B7: All Electric | C7: 45658 | D7: Commercial / Industrial | E7: 8 | F7: Nonresidential | G7: 11715.03 | H7: 369003.74 | I7: 15143.32 | J7: 0 | K7: 0 | L7: 0 | M7: 30179.01 | N7: 2128.47 | O7: 145.88972 | P7: 17 | Q7: 31 | R7: 1 | S7: SCE | T7: =2025 -> 2025
A8: New Construction | B8: All Electric | C8: 45658 | D8: Commercial / Industrial | E8: 9 | F8: Nonresidential | G8: 0 | H8: 176387.16 | I8: 15091.02 | J8: 0 | K8: 0 | L8: 0 | M8: 11608.94 | N8: 0 | O8: 79.625056 | P8: 2 | Q8: 19 | R8: 0 | S8: SCE | T8: =2025 -> 2025
A9: New Construction | B9: All Electric | C9: 45658 | D9: Commercial / Industrial | E9: 10 | F9: Nonresidential | G9: 12051.9 | H9: 27211.39 | I9: 21954.27 | J9: 0 | K9: 0 | L9: 0 | M9: 21230.08 | N9: 0 | O9: 151.98325 | P9: 14 | Q9: 34 | R9: 1 | S9: SCE | T9: =2025 -> 2025
A10: New Construction | B10: All Electric | C10: 45658 | D10: Commercial / Industrial | E10: 13 | F10: Nonresidential | G10: 0 | H10: 232453.87 | I10: 0 | J10: 0 | K10: 0 | L10: 0 | M10: 26598.16 | N10: 0 | O10: 101.01833 | P10: 4 | Q10: 12 | R10: 0 | S10: SCE | T10: =2025 -> 2025
A11: New Construction | B11: All Electric | C11: 45658 | D11: Commercial / Industrial | E11: 14 | F11: Nonresidential | G11: 0 | H11: 837364.93 | I11: 1498.26 | J11: 0 | K11: 0 | L11: 0 | M11: 42533.15 | N11: 0 | O11: 104.20254 | P11: 3 | Q11: 7 | R11: 0 | S11: SCE | T11: =2025 -> 2025
A12: New Construction | B12: All Electric | C12: 45658 | D12: Commercial / Industrial | E12: 15 | F12: Nonresidential | G12: 0 | H12: 0 | I12: 0 | J12: 0 | K12: 0 | L12: 0 | M12: 0 | N12: 0 | O12: N/A | P12: 0 | Q12: 6 | R12: 0 | S12: SCE | T12: =2025 -> 2025
A13: New Construction | B13: All Electric | C13: 45658 | D13: Commercial / Industrial | E13: 16 | F13: Nonresidential | G13: 0 | H13: 24934.69 | I13: 2259.15 | J13: 0 | K13: 0 | L13: 0 | M13: 0 | N13: 0 | O13: 164.16595 | P13: 2 | Q13: 5 | R13: 0 | S13: SCE | T13: =2025 -> 2025
A14: New Construction | B14: All Electric | C14: 45658 | D14: Residential | E14: 6 | F14: Multi-Family | G14: 0 | H14: 0 | I14: 0 | J14: 0 | K14: 0 | L14: 0 | M14: 0 | N14: 0 | O14: N/A | P14: 0 | Q14: 20 | R14: 3 | S14: SCE | T14: =2025 -> 2025
A15: New Construction | B15: All Electric | C15: 45658 | D15: Residential | E15: 6 | F15: Single-Family | G15: 600.98 | H15: 32135.4 | I15: 1709.26 | J15: 0 | K15: 0 | L15: 0 | M15: 2389.4 | N15: 0 | O15: 69.052254 | P15: 15 | Q15: 1 | R15: 0 | S15: SCE | T15: =2025 -> 2025
A16: New Construction | B16: All Electric | C16: 45658 | D16: Residential | E16: 8 | F16: Multi-Family | G16: 21343.31 | H16: 28811.27 | I16: 0 | J16: 0 | K16: 0 | L16: 0 | M16: 22276.9 | N16: 0 | O16: 87.034229 | P16: 4 | Q16: 15 | R16: 1 | S16: SCE | T16: =2025 -> 2025
A17: New Construction | B17: All Electric | C17: 45658 | D17: Residential | E17: 8 | F17: Single-Family | G17: 1113.46 | H17: 67664.35 | I17: 1901.8 | J17: 0 | K17: 0 | L17: 0 | M17: 14505.9 | N17: 78636.62 | O17: 68.319214 | P17: 19 | Q17: 2 | R17: 3 | S17: SCE | T17: =2025 -> 2025
A18: New Construction | B18: All Electric | C18: 45658 | D18: Residential | E18: 9 | F18: Multi-Family | G18: 0 | H18: 3107.94 | I18: 0 | J18: 0 | K18: 0 | L18: 0 | M18: 0 | N18: 0 | O18: 284.59858 | P18: 1 | Q18: 48 | R18: 2 | S18: SCE | T18: =2025 -> 2025
A19: New Construction | B19: All Electric | C19: 45658 | D19: Residential | E19: 9 | F19: Single-Family | G19: 0 | H19: 26169.88 | I19: 0 | J19: 0 | K19: 0 | L19: 0 | M19: 20143.13 | N19: 126177.32 | O19: 64.29254 | P19: 21 | Q19: 1 | R19: 0 | S19: SCE | T19: =2025 -> 2025
A20: New Construction | B20: All Electric | C20: 45658 | D20: Residential | E20: 10 | F20: Multi-Family | G20: 0 | H20: 4160.66 | I20: 0 | J20: 0 | K20: 0 | L20: 0 | M20: 0 | N20: 0 | O20: 90.859167 | P20: 2 | Q20: 66 | R20: 7 | S20: SCE | T20: =2025 -> 2025
A21: New Construction | B21: All Electric | C21: 45658 | D21: Residential | E21: 10 | F21: Single-Family | G21: 14423.28 | H21: 93718.2 | I21: 16561.84 | J21: 0 | K21: 0 | L21: 0 | M21: 70334.83 | N21: 534448.73 | O21: 135.72584 | P21: 22 | Q21: 0 | R21: 0 | S21: SCE | T21: =2025 -> 2025
A22: New Construction | B22: All Electric | C22: 45658 | D22: Residential | E22: 13 | F22: Multi-Family | G22: 0 | H22: 1306.3 | I22: 0 | J22: 0 | K22: 0 | L22: 0 | M22: 0 | N22: 0 | O22: 39.581986 | P22: 2 | Q22: 8 | R22: 5 | S22: SCE | T22: =2025 -> 2025
A23: New Construction | B23: All Electric | C23: 45658 | D23: Residential | E23: 13 | F23: Single-Family | G23: 0 | H23: 3068.23 | I23: 298130.71 | J23: 0 | K23: 0 | L23: 0 | M23: 0 | N23: 0 | O23: 77.663108 | P23: 4 | Q23: 3 | R23: 0 | S23: SCE | T23: =2025 -> 2025
A24: New Construction | B24: All Electric | C24: 45658 | D24: Residential | E24: 14 | F24: Multi-Family | G24: 0 | H24: 3051.95 | I24: 0 | J24: 0 | K24: 0 | L24: 0 | M24: 0 | N24: 0 | O24: 37.901333 | P24: 4 | Q24: 63 | R24: 0 | S24: SCE | T24: =2025 -> 2025
A25: New Construction | B25: All Electric | C25: 45658 | D25: Residential | E25: 14 | F25: Single-Family | G25: 24966.71 | H25: 60639.74 | I25: 10341.41 | J25: 0 | K25: 0 | L25: 0 | M25: 6292.2 | N25: 0 | O25: 87.305829 | P25: 27 | Q25: 4 | R25: 0 | S25: SCE | T25: =2025 -> 2025
A26: New Construction | B26: All Electric | C26: 45658 | D26: Residential | E26: 15 | F26: Multi-Family | G26: 0 | H26: 0 | I26: 0 | J26: 0 | K26: 0 | L26: 0 | M26: 0 | N26: 0 | O26: N/A | P26: 0 | Q26: 7 | R26: 0 | S26: SCE | T26: =2025 -> 2025
A27: New Construction | B27: All Electric | C27: 45658 | D27: Residential | E27: 15 | F27: Single-Family | G27: 2128.27 | H27: 7378.46 | I27: 0 | J27: 0 | K27: 0 | L27: 0 | M27: 1808.44 | N27: 0 | O27: 48.921386 | P27: 3 | Q27: 0 | R27: 0 | S27: SCE | T27: =2025 -> 2025
A28: New Construction | B28: All Electric | C28: 45658 | D28: Residential | E28: 16 | F28: Multi-Family | G28: 0 | H28: 6881.45 | I28: 0 | J28: 0 | K28: 0 | L28: 0 | M28: 0 | N28: 0 | O28: 227.83416 | P28: 3 | Q28: 6 | R28: 0 | S28: SCE | T28: =2025 -> 2025
A29: New Construction | B29: All Electric | C29: 45658 | D29: Residential | E29: 16 | F29: Single-Family | G29: 0 | H29: 4024.96 | I29: 0 | J29: 0 | K29: 0 | L29: 0 | M29: 0 | N29: 0 | O29: 168.63178 | P29: 4 | Q29: 1 | R29: 0 | S29: SCE | T29: =2025 -> 2025
A30: New Construction | B30: All Electric | C30: 45689 | D30: Agriculture | E30: 6 | F30: Nonresidential | G30: 0 | H30: 637.61 | I30: 0 | J30: 0 | K30: 0 | L30: 0 | M30: 0 | N30: 0 | O30: 51.598835 | P30: 1 | Q30: 1 | R30: 0 | S30: SCE | T30: =2025 -> 2025
A31: New Construction | B31: All Electric | C31: 45689 | D31: Agriculture | E31: 9 | F31: Nonresidential | G31: 0 | H31: 0 | I31: 0 | J31: 0 | K31: 0 | L31: 0 | M31: 0 | N31: 0 | O31: N/A | P31: 0 | Q31: 3 | R31: 0 | S31: SCE | T31: =2025 -> 2025
A32: New Construction | B32: All Electric | C32: 45689 | D32: Agriculture | E32: 13 | F32: Nonresidential | G32: 0 | H32: 140535.03 | I32: 0 | J32: 0 | K32: 0 | L32: 0 | M32: 2848.18 | N32: 0 | O32: 55.039584 | P32: 2 | Q32: 2 | R32: 0 | S32: SCE | T32: =2025 -> 2025
A33: New Construction | B33: All Electric | C33: 45689 | D33: Commercial / Industrial | E33: 6 | F33: Nonresidential | G33: 0 | H33: 38328.74 | I33: 6921.12 | J33: 0 | K33: 0 | L33: 0 | M33: 0 | N33: 0 | O33: 163.50408 | P33: 1 | Q33: 22 | R33: 0 | S33: SCE | T33: =2025 -> 2025
A34: New Construction | B34: All Electric | C34: 45689 | D34: Commercial / Industrial | E34: 8 | F34: Nonresidential | G34: 4653.45 | H34: 109160.85 | I34: 19530 | J34: 0 | K34: 0 | L34: 0 | M34: 13351.96 | N34: 0 | O34: 98.341146 | P34: 8 | Q34: 11 | R34: 1 | S34: SCE | T34: =2025 -> 2025
A35: New Construction | B35: All Electric | C35: 45689 | D35: Commercial / Industrial | E35: 9 | F35: Nonresidential | G35: 0 | H35: 557446.14 | I35: 205499.55 | J35: 0 | K35: 0 | L35: 0 | M35: 34385.38 | N35: 0 | O35: 98.561297 | P35: 8 | Q35: 29 | R35: 0 | S35: SCE | T35: =2025 -> 2025
A36: New Construction | B36: All Electric | C36: 45689 | D36: Commercial / Industrial | E36: 10 | F36: Nonresidential | G36: 218929.18 | H36: 601816.47 | I36: 3705.91 | J36: 0 | K36: 0 | L36: 0 | M36: 131538.86 | N36: 0 | O36: 139.02361 | P36: 26 | Q36: 63 | R36: 2 | S36: SCE | T36: =2025 -> 2025
A37: New Construction | B37: All Electric | C37: 45689 | D37: Commercial / Industrial | E37: 13 | F37: Nonresidential | G37: 0 | H37: 60918.92 | I37: 0 | J37: 0 | K37: 0 | L37: 0 | M37: 0 | N37: 0 | O37: 159.40527 | P37: 3 | Q37: 6 | R37: 2 | S37: SCE | T37: =2025 -> 2025
A38: New Construction | B38: All Electric | C38: 45689 | D38: Commercial / Industrial | E38: 14 | F38: Nonresidential | G38: 1435.55 | H38: 167074.64 | I38: 51473.65 | J38: 0 | K38: 0 | L38: 0 | M38: 20570.42 | N38: 0 | O38: 177.32804 | P38: 7 | Q38: 14 | R38: 0 | S38: SCE | T38: =2025 -> 2025
A39: New Construction | B39: All Electric | C39: 45689 | D39: Commercial / Industrial | E39: 15 | F39: Nonresidential | G39: 75332.48 | H39: 457654.81 | I39: 4464.03 | J39: 0 | K39: 0 | L39: 0 | M39: 120856.81 | N39: 0 | O39: 156.98475 | P39: 3 | Q39: 8 | R39: 0 | S39: SCE | T39: =2025 -> 2025
A40: New Construction | B40: All Electric | C40: 45689 | D40: Commercial / Industrial | E40: 16 | F40: Nonresidential | G40: 0 | H40: 3633.64 | I40: 2441.89 | J40: 0 | K40: 0 | L40: 0 | M40: 0 | N40: 0 | O40: 214.54488 | P40: 2 | Q40: 6 | R40: 0 | S40: SCE | T40: =2025 -> 2025
...

Sheet SDGE_Q1_2025
A1: New Construction / Upgrade | B1: Mixed Fuel / All Electric | C1: Months | D1: Customer Class | E1: Baseline / Climate Zone | F1: Multi Dwelling | G1: Total Discounts (Non-Exempted Projects) | H1: Total Allowances (Non-Exempted Projects) | I1: Total Refund Payments Provided to Builders (Non-Exempted Projects) | J1: Total Discounts (Exempted projects) | K1: Total Allowances (Exempted projects) | L1: Total Refund Payments Provided to Builders (Exempted projects) | M1: Total Estimated Non-Refundable | N1: Total Estimated Refundable | O1: Average Number of days between full payment and Project Energization | P1: Total Electric Line Extensions Energized | Q1: Total Electric Line Extension Applications (IOU Installed) | R1: Total Electric Line Extension Applications (Applicant Installed) | S1: IoU | T1: Year
A2: New Construction | B2: All Electric | C2: 45658 | D2: Commercial | E2: Unknown | F2: Nonresidential | G2: 0 | H2: 0 | I2: 0 | J2: 0 | K2: 0 | L2: 0 | M2: 0 | N2: 0 | O2: 0 | P2: 1 | Q2: 37 | R2: 0 | S2: SDGE | T2: 2025
A3: New Construction | B3: All Electric | C3: 45658 | D3: Residential | E3: Unknown | F3: Unknown | G3: 0 | H3: 0 | I3: 0 | J3: 0 | K3: 0 | L3: 0 | M3: 0 | N3: 0 | O3: 0 | P3: 1 | Q3: 5 | R3: 0 | S3: SDGE | T3: 2025
A4: New Construction | B4: All Electric | C4: 45658 | D4: Commercial | E4: 6 | F4: Nonresidential | G4: 0 | H4: 0 | I4: 0 | J4: 0 | K4: 0 | L4: 0 | M4: 0 | N4: 0 | O4: 47 | P4: 2 | Q4: 13 | R4: 0 | S4: SDGE | T4: 2025
A5: New Construction | B5: All Electric | C5: 45658 | D5: Residential | E5: 6 | F5: Unknown | G5: 0 | H5: 0 | I5: 0 | J5: 0 | K5: 0 | L5: 0 | M5: 0 | N5: 0 | O5: 0 | P5: 4 | Q5: 13 | R5: 0 | S5: SDGE | T5: 2025
A6: New Construction | B6: All Electric | C6: 45658 | D6: Residential | E6: 6 | F6: Single-Family | G6: 0 | H6: 2610.91 | I6: 0 | J6: 0 | K6: 0 | L6: 0 | M6: 853 | N6: 0 | O6: 161 | P6: 4 | Q6: 1 | R6: 0 | S6: SDGE | T6: 2025
A7: New Construction | B7: All Electric | C7: 45658 | D7: Commercial | E7: 7 | F7: Nonresidential | G7: 0 | H7: 59343.11 | I7: 0 | J7: 0 | K7: 0 | L7: 0 | M7: 260 | N7: 0 | O7: 88 | P7: 21 | Q7: 106 | R7: 0 | S7: SDGE | T7: 2025
A8: New Construction | B8: All Electric | C8: 45658 | D8: Residential | E8: 7 | F8: Unknown | G8: 15489 | H8: 48292.14 | I8: 0 | J8: 0 | K8: 0 | L8: 0 | M8: 47726 | N8: 0 | O8: 269 | P8: 74 | Q8: 162 | R8: 0 | S8: SDGE | T8: 2025
A9: New Construction | B9: All Electric | C9: 45658 | D9: Residential | E9: 7 | F9: Multi-Family | G9: 0 | H9: 10560.6 | I9: 0 | J9: 0 | K9: 0 | L9: 0 | M9: 1120 | N9: 0 | O9: 147 | P9: 3 | Q9: 6 | R9: 0 | S9: SDGE | T9: 2025
A10: New Construction | B10: All Electric | C10: 45658 | D10: Residential | E10: 7 | F10: Single-Family | G10: 31803.25 | H10: 61925.62 | I10: 0 | J10: 0 | K10: 0 | L10: 0 | M10: 55552 | N10: 46500.62 | O10: 181 | P10: 14 | Q10: 49 | R10: 0 | S10: SDGE | T10: 2025
A11: New Construction | B11: All Electric | C11: 45658 | D11: Commercial | E11: 10 | F11: Nonresidential | G11: 0 | H11: 35317.84 | I11: 0 | J11: 0 | K11: 0 | L11: 0 | M11: 1677 | N11: 0 | O11: 116 | P11: 6 | Q11: 29 | R11: 0 | S11: SDGE | T11: 2025
A12: New Construction | B12: All Electric | C12: 45658 | D12: Residential | E12: 10 | F12: Unknown | G12: 0 | H12: 17630.46 | I12: 0 | J12: 0 | K12: 0 | L12: 0 | M12: 34487 | N12: 0 | O12: 95 | P12: 20 | Q12: 46 | R12: 0 | S12: SDGE | T12: 2025
A13: New Construction | B13: All Electric | C13: 45658 | D13: Residential | E13: 10 | F13: Multi-Family | G13: 18690.53 | H13: 1903.89 | I13: 0 | J13: 0 | K13: 0 | L13: 0 | M13: 34560 | N13: 37381.06 | O13: 467 | P13: 2 | Q13: 3 | R13: 0 | S13: SDGE | T13: 2025
A14: New Construction | B14: All Electric | C14: 45658 | D14: Residential | E14: 10 | F14: Single-Family | G14: 22284 | H14: 19293.38 | I14: 0 | J14: 0 | K14: 0 | L14: 0 | M14: 27349 | N14: 0 | O14: 325 | P14: 18 | Q14: 41 | R14: 0 | S14: SDGE | T14: 2025
A15: New Construction | B15: All Electric | C15: 45658 | D15: Residential | E15: 14 | F15: Unknown | G15: 0 | H15: 0 | I15: 0 | J15: 0 | K15: 0 | L15: 0 | M15: 0 | N15: 0 | O15: 64 | P15: 1 | Q15: 0 | R15: 0 | S15: SDGE | T15: 2025
A16: New Construction | B16: Mixed Fuel | C16: 45658 | D16: Commercial | E16: Unknown | F16: Nonresidential | G16: 0 | H16: 0 | I16: 0 | J16: 0 | K16: 0 | L16: 0 | M16: 0 | N16: 0 | O16: 138 | P16: 1 | Q16: 0 | R16: 0 | S16: SDGE | T16: 2025
A17: New Construction | B17: Mixed Fuel | C17: 45658 | D17: Residential | E17: Unknown | F17: Unknown | G17: 0 | H17: 743.78 | I17: 0 | J17: 0 | K17: 0 | L17: 0 | M17: 0 | N17: 0 | O17: 0 | P17: 7 | Q17: 4 | R17: 0 | S17: SDGE | T17: 2025
A18: New Construction | B18: Mixed Fuel | C18: 45658 | D18: Commercial | E18: 6 | F18: Nonresidential | G18: 0 | H18: 0 | I18: 0 | J18: 0 | K18: 0 | L18: 0 | M18: 23663 | N18: 0 | O18: 230 | P18: 1 | Q18: 0 | R18: 0 | S18: SDGE | T18: 2025
A19: New Construction | B19: Mixed Fuel | C19: 45658 | D19: Residential | E19: 6 | F19: Unknown | G19: 0 | H19: 1142.36 | I19: 0 | J19: 0 | K19: 0 | L19: 0 | M19: 0 | N19: 0 | O19: 0 | P19: 1 | Q19: 0 | R19: 0 | S19: SDGE | T19: 2025
A20: New Construction | B20: Mixed Fuel | C20: 45658 | D20: Residential | E20: 6 | F20: Single-Family | G20: 6074.04 | H20: 4602.4 | I20: 0 | J20: 0 | K20: 0 | L20: 0 | M20: 529 | N20: 0 | O20: 436 | P20: 3 | Q20: 0 | R20: 0 | S20: SDGE | T20: 2025
A21: New Construction | B21: Mixed Fuel | C21: 45658 | D21: Commercial | E21: 7 | F21: Nonresidential | G21: 63755.99 | H21: 70545.02 | I21: 0 | J21: 0 | K21: 0 | L21: 0 | M21: 128430 | N21: 8945 | O21: 214 | P21: 28 | Q21: 31 | R21: 0 | S21: SDGE | T21: 2025
A22: New Construction | B22: Mixed Fuel | C22: 45658 | D22: Industrial | E22: 7 | F22: Nonresidential | G22: 0 | H22: 27600.72 | I22: 0 | J22: 0 | K22: 0 | L22: 0 | M22: 0 | N22: 0 | O22: 0 | P22: 1 | Q22: 0 | R22: 0 | S22: SDGE | T22: 2025
A23: New Construction | B23: Mixed Fuel | C23: 45658 | D23: Residential | E23: 7 | F23: Unknown | G23: 274651.9 | H23: 16438.09 | I23: 0 | J23: 0 | K23: 0 | L23: 0 | M23: 380908 | N23: 0 | O23: 157 | P23: 58 | Q23: 64 | R23: 0 | S23: SDGE | T23: 2025
A24: New Construction | B24: Mixed Fuel | C24: 45658 | D24: Residential | E24: 7 | F24: Multi-Family | G24: 18708.3 | H24: 201584.93 | I24: 0 | J24: 0 | K24: 0 | L24: 0 | M24: 37632 | N24: 37416.61 | O24: 431 | P24: 13 | Q24: 1 | R24: 0 | S24: SDGE | T24: 2025
A25: New Construction | B25: Mixed Fuel | C25: 45658 | D25: Residential | E25: 7 | F25: Single-Family | G25: 515.45 | H25: 88033.52 | I25: 0 | J25: 0 | K25: 0 | L25: 0 | M25: 23163 | N25: 0 | O25: 246 | P25: 20 | Q25: 11 | R25: 0 | S25: SDGE | T25: 2025
A26: New Construction | B26: Mixed Fuel | C26: 45658 | D26: Commercial | E26: 10 | F26: Nonresidential | G26: 0 | H26: 0 | I26: 0 | J26: 0 | K26: 0 | L26: 0 | M26: 6504 | N26: 0 | O26: 124 | P26: 4 | Q26: 22 | R26: 0 | S26: SDGE | T26: 2025
A27: New Construction | B27: Mixed Fuel | C27: 45658 | D27: Residential | E27: 10 | F27: Unknown | G27: 0 | H27: 0 | I27: 0 | J27: 0 | K27: 0 | L27: 0 | M27: 4670 | N27: 0 | O27: 63 | P27: 4 | Q27: 17 | R27: 0 | S27: SDGE | T27: 2025
A28: New Construction | B28: Mixed Fuel | C28: 45658 | D28: Residential | E28: 10 | F28: Multi-Family | G28: 0 | H28: 53496.04 | I28: 0 | J28: 0 | K28: 0 | L28: 0 | M28: 5676 | N28: 0 | O28: 355 | P28: 1 | Q28: 2 | R28: 0 | S28: SDGE | T28: 2025
A29: New Construction | B29: Mixed Fuel | C29: 45658 | D29: Residential | E29: 10 | F29: Single-Family | G29: 0 | H29: 2228.38 | I29: 0 | J29: 0 | K29: 0 | L29: 0 | M29: 3967 | N29: 0 | O29: 122 | P29: 4 | Q29: 15 | R29: 0 | S29: SDGE | T29: 2025
A30: Upgrade | B30: All Electric | C30: 45658 | D30: Residential | E30: Unknown | F30: Unknown | G30: 0 | H30: 0 | I30: 0 | J30: 0 | K30: 0 | L30: 0 | M30: 0 | N30: 0 | O30: 0 | P30: 4 | Q30: 0 | R30: 0 | S30: SDGE | T30: 2025
A31: Upgrade | B31: All Electric | C31: 45658 | D31: Commercial | E31: 6 | F31: Nonresidential | G31: 0 | H31: 0 | I31: 0 | J31: 0 | K31: 0 | L31: 0 | M31: 0 | N31: 0 | O31: 0 | P31: 1 | Q31: 5 | R31: 0 | S31: SDGE | T31: 2025
A32: Upgrade | B32: All Electric | C32: 45658 | D32: Residential | E32: 6 | F32: Unknown | G32: 0 | H32: 21717.52 | I32: 0 | J32: 0 | K32: 0 | L32: 0 | M32: 0 | N32: 0 | O32: 0 | P32: 35 | Q32: 60 | R32: 0 | S32: SDGE | T32: 2025
A33: Upgrade | B33: All Electric | C33: 45658 | D33: Residential | E33: 6 | F33: Single-Family | G33: 0 | H33: 727.04 | I33: 0 | J33: 0 | K33: 0 | L33: 0 | M33: 0 | N33: 0 | O33: 0 | P33: 1 | Q33: 1 | R33: 0 | S33: SDGE | T33: 2025
A34: Upgrade | B34: All Electric | C34: 45658 | D34: Commercial | E34: 7 | F34: Nonresidential | G34: 0 | H34: 0 | I34: 0 | J34: 0 | K34: 0 | L34: 0 | M34: 0 | N34: 0 | O34: 69 | P34: 4 | Q34: 84 | R34: 0 | S34: SDGE | T34: 2025
A35: Upgrade | B35: All Electric | C35: 45658 | D35: Residential | E35: 7 | F35: Unknown | G35: 0 | H35: 264279.78 | I35: 0 | J35: 0 | K35: 0 | L35: 0 | M35: 9668 | N35: 0 | O35: 124 | P35: 281 | Q35: 445 | R35: 0 | S35: SDGE | T35: 2025
A36: Upgrade | B36: All Electric | C36: 45658 | D36: Residential | E36: 7 | F36: Multi-Family | G36: 0 | H36: 2412.15 | I36: 0 | J36: 0 | K36: 0 | L36: 0 | M36: 0 | N36: 0 | O36: 0 | P36: 1 | Q36: 5 | R36: 0 | S36: SDGE | T36: 2025
A37: Upgrade | B37: All Electric | C37: 45658 | D37: Residential | E37: 7 | F37: Single-Family | G37: 0 | H37: 0 | I37: 0 | J37: 0 | K37: 0 | L37: 0 | M37: 0 | N37: 0 | O37: 0 | P37: 1 | Q37: 12 | R37: 0 | S37: SDGE | T37: 2025
A38: Upgrade | B38: All Electric | C38: 45658 | D38: Commercial | E38: 8 | F38: Nonresidential | G38: 0 | H38: 0 | I38: 0 | J38: 0 | K38: 0 | L38: 0 | M38: 0 | N38: 0 | O38: 0 | P38: 1 | Q38: 0 | R38: 0 | S38: SDGE | T38: 2025
A39: Upgrade | B39: All Electric | C39: 45658 | D39: Residential | E39: 8 | F39: Unknown | G39: 0 | H39: 3981 | I39: 0 | J39: 0 | K39: 0 | L39: 0 | M39: 0 | N39: 0 | O39: 0 | P39: 5 | Q39: 10 | R39: 0 | S39: SDGE | T39: 2025
A40: Upgrade | B40: All Electric | C40: 45658 | D40: Commercial | E40: 10 | F40: Nonresidential | G40: 0 | H40: 0 | I40: 0 | J40: 0 | K40: 0 | L40: 0 | M40: 0 | N40: 0 | O40: 0 | P40: 4 | Q40: 13 | R40: 0 | S40: SDGE | T40: 2025
...
