Workbook

Sheet Reference Sheet
A1: 2024
A2: Report Due: May 01, 2024
A3: Reporting Period: January 01, 2023 - December 31, 2023
A5: 2025
A6: Report Due: May 01, 2025
A7: Reporting Period: January 01, 2024 - December 31, 2024
A9: 2026
A10: Report Due: May 01, 2026
A11: Reporting Period: January 01, 2025 - December 31, 2025
A12: Note: Beginning 2026, Refundable Actual Net to Builders and Non-Refundable Actual Net to Builders need to be included in the reported data.

Sheet Summary
B2: PG&E - 2023 Line Extension Requests Received (Applications)
B3: Customer Class | C3: Mixed Fuel | D3: All-Electric | E3: Total | F3: Percent All-Electric
B4: Commercial | C4: =SUM('Mixed-Fuel New Construction'!J10,'Mixed-Fuel New Construction'!J22,'Mixed-Fuel New Construction'!J34,'Mixed-Fuel New Construction'!J46,'Mixed-Fuel New Construction'!J58,'Mixed-Fuel New Construction'!J70,'Mixed-Fuel New Construction'!J82,'Mixed-Fuel New Construction'!J94,'Mixed-Fuel New Construction'!J106,'Mixed-Fuel New Construction'!J118,'Mixed-Fuel New Construction'!J130,'Mixed-Fuel New Construction'!J142) | D4: =SUM('All Electric New Construction'!J8,'All Electric New Construction'!J20,'All Electric New Construction'!J32,'All Electric New Construction'!J44,'All Electric New Construction'!J56,'All Electric New Construction'!J68,'All Electric New Construction'!J80,'All Electric New Construction'!J92,'All Electric New Construction'!J104,'All Electric New Construction'!J116,'All Electric New Construction'!J128,'All Electric New Construction'!J140) | E4: =SUM(C4:D4) | F4: =D4/E4
B5: Mixed Use (Commercial / Residential) | C5: =SUM('Mixed-Fuel New Construction'!J12,'Mixed-Fuel New Construction'!J24,'Mixed-Fuel New Construction'!J36,'Mixed-Fuel New Construction'!J48,'Mixed-Fuel New Construction'!J60,'Mixed-Fuel New Construction'!J72,'Mixed-Fuel New Construction'!J84,'Mixed-Fuel New Construction'!J96,'Mixed-Fuel New Construction'!J108,'Mixed-Fuel New Construction'!J120,'Mixed-Fuel New Construction'!J132,'Mixed-Fuel New Construction'!J144) | D5: =SUM('All Electric New Construction'!J10,'All Electric New Construction'!J22,'All Electric New Construction'!J34,'All Electric New Construction'!J46,'All Electric New Construction'!J58,'All Electric New Construction'!J70,'All Electric New Construction'!J82,'All Electric New Construction'!J94,'All Electric New Construction'!J106,'All Electric New Construction'!J118,'All Electric New Construction'!J130,'All Electric New Construction'!J142) | E5: =SUM(C5:D5) | F5: =D5/E5
B6: Residential | C6: =SUM('Mixed-Fuel New Construction'!J13,'Mixed-Fuel New Construction'!J25,'Mixed-Fuel New Construction'!J37,'Mixed-Fuel New Construction'!J49,'Mixed-Fuel New Construction'!J61,'Mixed-Fuel New Construction'!J73,'Mixed-Fuel New Construction'!J85,'Mixed-Fuel New Construction'!J97,'Mixed-Fuel New Construction'!J109,'Mixed-Fuel New Construction'!J121,'Mixed-Fuel New Construction'!J133,'Mixed-Fuel New Construction'!J145) | D6: =SUM('All Electric New Construction'!J11,'All Electric New Construction'!J23,'All Electric New Construction'!J35,'All Electric New Construction'!J47,'All Electric New Construction'!J59,'All Electric New Construction'!J71,'All Electric New Construction'!J83,'All Electric New Construction'!J95,'All Electric New Construction'!J107,'All Electric New Construction'!J119,'All Electric New Construction'!J131,'All Electric New Construction'!J143) | E6: =SUM(C6:D6) | F6: =D6/E6
B7: Industrial | C7: =SUM('Mixed-Fuel New Construction'!J11,'Mixed-Fuel New Construction'!J23,'Mixed-Fuel New Construction'!J35,'Mixed-Fuel New Construction'!J47,'Mixed-Fuel New Construction'!J59,'Mixed-Fuel New Construction'!J71,'Mixed-Fuel New Construction'!J83,'Mixed-Fuel New Construction'!J95,'Mixed-Fuel New Construction'!J107,'Mixed-Fuel New Construction'!J119,'Mixed-Fuel New Construction'!J131,'Mixed-Fuel New Construction'!J143) | D7: =SUM('All Electric New Construction'!J9,'All Electric New Construction'!J21,'All Electric New Construction'!J33,'All Electric New Construction'!J45,'All Electric New Construction'!J57,'All Electric New Construction'!J69,'All Electric New Construction'!J81,'All Electric New Construction'!J93,'All Electric New Construction'!J105,'All Electric New Construction'!J117,'All Electric New Construction'!J129,'All Electric New Construction'!J141) | E7: =SUM(C7:D7) | F7: =D7/E7
B8: Agricultural | C8: =SUM('Mixed-Fuel New Construction'!J9,'Mixed-Fuel New Construction'!J21,'Mixed-Fuel New Construction'!J33,'Mixed-Fuel New Construction'!J45,'Mixed-Fuel New Construction'!J57,'Mixed-Fuel New Construction'!J69,'Mixed-Fuel New Construction'!J81,'Mixed-Fuel New Construction'!J93,'Mixed-Fuel New Construction'!J105,'Mixed-Fuel New Construction'!J117,'Mixed-Fuel New Construction'!J129,'Mixed-Fuel New Construction'!J141) | D8: =SUM('All Electric New Construction'!J7,'All Electric New Construction'!J19,'All Electric New Construction'!J31,'All Electric New Construction'!J43,'All Electric New Construction'!J55,'All Electric New Construction'!J67,'All Electric New Construction'!J79,'All Electric New Construction'!J91,'All Electric New Construction'!J103,'All Electric New Construction'!J115,'All Electric New Construction'!J127,'All Electric New Construction'!J139) | E8: =SUM(C8:D8) | F8: =D8/E8
B9: All Buildings (Comm + Res + Mixed) | C9: =SUM(C4,C5,C6) | D9: =SUM(D4,D5,D6) | E9: =SUM(E4,E5,E6) | F9: =D9/E9
B10: All Requests (Buildings + Ind + Ag) | C10: =SUM(C4:C8) | D10: =SUM(D4:D8) | E10: =SUM(E4:E8) | F10: =D10/E10
B12: SDG&E - 2023 Line Extension Requests Received (Applications)
B13: Customer Class | C13: Mixed Fuel | D13: All-Electric | E13: Total | F13: Percent All-Electric
B14: All Requests (Buildings + Ind + Ag) | C14: 1787 | D14: 12680 | E14: =SUM(C14:D14) | F14: =D14/E14
B16: PG&E & SDG&E Combined - 2023 Line Extension Requests Received (Applications)
B17: Customer Class | C17: Mixed Fuel | D17: All-Electric | E17: Total | F17: Percent All-Electric
B18: All Requests (Buildings + Ind + Ag) | C18: =SUM(C10+C14) | D18: =SUM(D10+D14) | E18: =SUM(C18:D18) | F18: =D18/E18

Sheet Mixed-Fuel New Construction
A1: Category: MIXED FUEL NEW CONSTRUCTION
A2: Dates to Pull: January 01, 2023 - December 31, 2023
A3: Due Date: May 01, 2024
A4: *Customer classes vary between IOU's
A6: 44927 | B6: Item 9 | C6: Item 12 | D6: Item 7 | E6: Item 10 | F6: Item 8 | G6: Item 11 | H6: Item 3 | I6: Item 2 | J6: Item 1 | K6: Item 4 | L6: Item 14
A7: Customer Class | B7: Total Discounts (Non-Exempted Projects) | C7: Total Discounts (Exempted projects) | D7: Total Allowances (Non-Exempted Projects) | E7: Total Allowances (Exempted projects) | F7: Total Refund Payments Provided to Builders (Non-Exempted Projects) | G7: Total Refund Payments Provided to Builders (Exempted projects) | H7: Total Estimated Non-Refundable | I7: Total Estimated Refundable | J7: Total Electric Line Extension Requests Received (Applications) | K7: Total Electric Line Extensions Energized | L7: Total Electric Line Extension Applications for Applicant Install
A8: Agency (City, County, Caltrans) | C8: 0 | E8: 0 | G8: 0 | J8: 2
A9: Agricultural | C9: 0 | E9: 0 | G9: 0
A10: Commercial | B10: 561528.82 | C10: 0 | D10: 645295.95 | E10: 0 | F10: 24887.99 | G10: 0 | H10: 106956.71 | I10: 1768353.6 | J10: 46 | K10: 10 | L10: 20
A11: Industrial | C11: 0 | E11: 0 | G11: 0 | J11: 6 | L11: 4
A12: Mixed Use (Commercial / Residential) | B12: 10376.376 | C12: 0 | D12: 273108.85 | E12: 0 | F12: 80646.47 | G12: 0 | H12: 23309.456 | I12: 293861.6 | J12: 11 | K12: 1 | L12: 4
A13: Residential | B13: 2944811.9 | C13: 0 | D13: 527015.84 | E13: 0 | F13: 39788.87 | G13: 0 | H13: 1798704 | I13: 6416639.7 | J13: 291 | K13: 55 | L13: 75
A14: Street and Outdoor area Lighting | C14: 0 | E14: 0 | G14: 0
A15: Telecommunications | C15: 0 | E15: 0 | G15: 0
A16: Temporary Services | C16: 0 | E16: 0 | G16: 0
A18: 45345
A19: Customer Class | B19: Total Discounts (Non-Exempted Projects) | C19: Total Discounts (Exempted projects) | D19: Total Allowances (Non-Exempted Projects) | E19: Total Allowances (Exempted projects) | F19: Total Refund Payments Provided to Builders (Non-Exempted Projects) | G19: Total Refund Payments Provided to Builders (Exempted projects) | H19: Total Estimated Non-Refundable | I19: Total Estimated Refundable | J19: Total Electric Line Extension Requests Received (Applications) | K19: Total Electric Line Extensions Energized | L19: Total Electric Line Extension Applications for Applicant Install
A20: Agency (City, County, Caltrans) | C20: 0 | E20: 0 | G20: 0 | J20: 1 | L20: 1
A21: Agricultural | C21: 0 | E21: 0 | G21: 0 | J21: 2
A22: Commercial | B22: 1250921.4 | C22: 0 | D22: 607933.84 | E22: 0 | F22: 88153.49 | G22: 0 | H22: 398885.4 | I22: 3109776.6 | J22: 41 | K22: 12 | L22: 14
A23: Industrial | B23: 19985.33 | C23: 0 | D23: 2130.1789 | E23: 0 | G23: 0 | H23: 3922.3624 | I23: 42100.84 | J23: 2 | K23: 1 | L23: 1
A24: Mixed Use (Commercial / Residential) | B24: 27084.664 | C24: 0 | D24: 557902.05 | E24: 0 | F24: 18084.64 | G24: 0 | H24: 66985.834 | I24: 612071.38 | J24: 5 | K24: 3 | L24: 4
A25: Residential | B25: 2759403.4 | C25: 0 | D25: 794196.11 | E25: 0 | F25: 74869.33 | G25: 0 | H25: 1990732.1 | I25: 6313002.9 | J25: 317 | K25: 88 | L25: 81
A26: Street and Outdoor area Lighting | C26: 0 | E26: 0 | G26: 0
A27: Telecommunications | C27: 0 | E27: 0 | G27: 0
A28: Temporary Services | C28: 0 | E28: 0 | G28: 0
A30: 44986
A31: Customer Class | B31: Total Discounts (Non-Exempted Projects) | C31: Total Discounts (Exempted projects) | D31: Total Allowances (Non-Exempted Projects) | E31: Total Allowances (Exempted projects) | F31: Total Refund Payments Provided to Builders (Non-Exempted Projects) | G31: Total Refund Payments Provided to Builders (Exempted projects) | H31: Total Estimated Non-Refundable | I31: Total Estimated Refundable | J31: Total Electric Line Extension Requests Received (Applications) | K31: Total Electric Line Extensions Energized | L31: Total Electric Line Extension Applications for Applicant Install
A32: Agency (City, County, Caltrans) | C32: 0 | E32: 0 | G32: 0 | J32: 2 | L32: 2
A33: Agricultural | C33: 0 | E33: 0 | G33: 0 | J33: 1 | L33: 1
A34: Commercial | B34: 1001094.2 | C34: 0 | D34: 393171.91 | E34: 0 | F34: 1269.21 | G34: 0 | H34: 147700.98 | I34: 2395360.2 | J34: 45 | K34: 16 | L34: 19
A35: Industrial | C35: 0 | E35: 0 | F35: 27700.21 | G35: 0 | J35: 2 | K35: 2 | L35: 1
A36: Mixed Use (Commercial / Residential) | B36: 244574.57 | C36: 0 | D36: 124575.09 | E36: 0 | G36: 0 | H36: 91186.971 | I36: 613724.22 | J36: 8 | K36: 2 | L36: 5
A37: Residential | B37: 4401405.6 | C37: 0 | D37: 886275.98 | E37: 0 | F37: 6405.24 | G37: 0 | H37: 2547604.4 | I37: 9689087.2 | J37: 377 | K37: 56 | L37: 108
A38: Street and Outdoor area Lighting | C38: 0 | E38: 0 | G38: 0
A39: Telecommunications | C39: 0 | E39: 0 | G39: 0
A40: Temporary Services | C40: 0 | E40: 0 | G40: 0
A42: 45017
A43: Customer Class | B43: Total Discounts (Non-Exempted Projects) | C43: Total Discounts (Exempted projects) | D43: Total Allowances (Non-Exempted Projects) | E43: Total Allowances (Exempted projects) | F43: Total Refund Payments Provided to Builders (Non-Exempted Projects) | G43: Total Refund Payments Provided to Builders (Exempted projects) | H43: Total Estimated Non-Refundable | I43: Total Estimated Refundable | J43: Total Electric Line Extension Requests Received (Applications) | K43: Total Electric Line Extensions Energized | L43: Total Electric Line Extension Applications for Applicant Install
A44: Agency (City, County, Caltrans) | C44: 0 | E44: 0 | G44: 0 | J44: 5 | L44: 1
...

Sheet All Electric New Construction
A1: Category: All Electric New Construction
A2: Dates to Pull: January 01, 2023 - December 31, 2023
A3: Due Date: May 01, 2024
A4: 44927 | B4: Item 9 | C4: Item 12 | D4: Item 7 | E4: Item 10 | F4: Item 8 | G4: Item 11 | H4: Item 3 | I4: Item 2 | J4: Item 1 | K4: Item 4 | L4: Item 14
A5: Customer Class | B5: Total Discounts (Non-Exempted Projects) | C5: Total Discounts (Exempted projects) | D5: Total Allowances (Non-Exempted Projects) | E5: Total Allowances (Exempted projects) | F5: Total Refund Payments Provided to Builders (Non-Exempted Projects) | G5: Total Refund Payments Provided to Builders (Exempted projects) | H5: Total Estimated Non-Refundable | I5: Total Estimated Refundable | J5: Total Electric Line Extension Requests Received (Applications) | K5: Total Electric Line Extensions Energized | L5: Total Electric Line Extension Applications for Applicant Install
A6: Agency (City, County, Caltrans) | B6: 17836.433 | C6: 0 | D6: 3555.6748 | E6: 0 | G6: 0 | H6: 13939.303 | I6: 39228.541 | J6: 45 | L6: 23
A7: Agricultural | B7: 328108.68 | C7: 0 | D7: 1391260.1 | E7: 0 | F7: 95518.83 | G7: 0 | H7: 118770.51 | I7: 2047477.5 | J7: 133 | K7: 45 | L7: 24
A8: Commercial | B8: 770881.07 | C8: 0 | D8: 568141.18 | E8: 0 | F8: 36684.54 | G8: 0 | H8: 569063.57 | I8: 2109903.3 | J8: 190 | K8: 51 | L8: 46
A9: Industrial | B9: 0 | C9: 0 | D9: 8688.494 | E9: 0 | G9: 0 | H9: 1378.9624 | I9: 8688.494 | J9: 11 | K9: 1 | L9: 2
A10: Mixed Use (Commercial / Residential) | B10: 46416.55 | C10: 0 | D10: 20948.271 | E10: 0 | F10: 2495.33 | G10: 0 | H10: 15963.766 | I10: 113781.37 | J10: 22 | K10: 1 | L10: 8
A11: Residential | B11: 845001.9 | C11: 0 | D11: 1239279.9 | E11: 0 | F11: 2340.78 | G11: 0 | H11: 1375024.3 | I11: 2929283.7 | J11: 687 | K11: 86 | L11: 152
A12: Street and Outdoor area Lighting | C12: 0 | E12: 0 | G12: 0 | H12: 8507.5444 | J12: 32 | K12: 5 | L12: 6
A13: Telecommunications | B13: 69817.668 | C13: 0 | D13: 17818.699 | E13: 0 | G13: 0 | H13: 71867.123 | I13: 157454.03 | J13: 149 | K13: 6 | L13: 13
A14: Temporary Services | B14: 3449.4836 | C14: 0 | D14: 712.74797 | E14: 0 | G14: 0 | H14: 29984.863 | I14: 7611.7152 | K14: 7
B15: =SUM(B6:B14)
A16: 45345
A17: Customer Class | B17: Total Discounts (Non-Exempted Projects) | C17: Total Discounts (Exempted projects) | D17: Total Allowances (Non-Exempted Projects) | E17: Total Allowances (Exempted projects) | F17: Total Refund Payments Provided to Builders (Non-Exempted Projects) | G17: Total Refund Payments Provided to Builders (Exempted projects) | H17: Total Estimated Non-Refundable | I17: Total Estimated Refundable | J17: Total Electric Line Extension Requests Received (Applications) | K17: Total Electric Line Extensions Energized | L17: Total Electric Line Extension Applications for Applicant Install
A18: Agency (City, County, Caltrans) | B18: 17713.181 | C18: 0 | D18: 1425.4959 | E18: 0 | G18: 0 | H18: 16104.112 | I18: 36851.858 | J18: 35 | K18: 1 | L18: 13
A19: Agricultural | B19: 345955.97 | C19: 0 | D19: 2333330.5 | E19: 0 | F19: 48749.36 | G19: 0 | H19: 75197.637 | I19: 3025242.4 | J19: 105 | K19: 61 | L19: 22
A20: Commercial | B20: 770418.56 | C20: 0 | D20: 808433.51 | E20: 0 | F20: 105361.85 | G20: 0 | H20: 353523.39 | I20: 2349270.6 | J20: 206 | K20: 37 | L20: 51
A21: Industrial | B21: 54429.753 | C21: 0 | D21: 518576.74 | E21: 0 | F21: 1296497.1 | G21: 0 | H21: 34191.082 | I21: 627436.24 | J21: 22 | K21: 4 | L21: 9
A22: Mixed Use (Commercial / Residential) | B22: 48888.14 | C22: 0 | D22: 736689.52 | E22: 0 | F22: 2184.25 | G22: 0 | H22: 138090.11 | I22: 834465.8 | J22: 14 | K22: 3 | L22: 8
A23: Residential | B23: 578541.93 | C23: 0 | D23: 1166225.1 | E23: 0 | F23: 50950.44 | G23: 0 | H23: 1352308.9 | I23: 2323309 | J23: 736 | K23: 146 | L23: 144
A24: Street and Outdoor area Lighting | B24: 12555.399 | C24: 0 | D24: 712.74797 | E24: 0 | G24: 0 | H24: 44179.793 | I24: 25823.546 | J24: 34 | K24: 2 | L24: 7
A25: Telecommunications | B25: 298048.23 | C25: 0 | D25: 18531.447 | E25: 0 | G25: 0 | H25: 96184.454 | I25: 614627.9 | J25: 165 | K25: 1 | L25: 8
A26: Temporary Services | B26: 0 | C26: 0 | D26: 0 | E26: 0 | G26: 0 | H26: 3800.6964 | I26: 0 | K26: 4
A28: 44986
A29: Customer Class | B29: Total Discounts (Non-Exempted Projects) | C29: Total Discounts (Exempted projects) | D29: Total Allowances (Non-Exempted Projects) | E29: Total Allowances (Exempted projects) | F29: Total Refund Payments Provided to Builders (Non-Exempted Projects) | G29: Total Refund Payments Provided to Builders (Exempted projects) | H29: Total Estimated Non-Refundable | I29: Total Estimated Refundable | J29: Total Electric Line Extension Requests Received (Applications) | K29: Total Electric Line Extensions Energized | L29: Total Electric Line Extension Applications for Applicant Install
A30: Agency (City, County, Caltrans) | B30: 127172.15 | C30: 0 | D30: 84224.564 | E30: 0 | G30: 0 | H30: 79728.304 | I30: 338568.86 | J30: 60 | K30: 2 | L30: 39
A31: Agricultural | B31: 770975.14 | C31: 0 | D31: 3181840.1 | E31: 0 | F31: 82929.06 | G31: 0 | H31: 161668.15 | I31: 4723790.4 | J31: 125 | K31: 19 | L31: 19
A32: Commercial | B32: 1743833.5 | C32: 0 | D32: 1491301.4 | E32: 0 | F32: 55492 | G32: 0 | H32: 552004.48 | I32: 4978968.5 | J32: 207 | K32: 32 | L32: 43
A33: Industrial | B33: 625280 | C33: 0 | D33: 311930.04 | E33: 0 | G33: 0 | H33: 126471.01 | I33: 1562490 | J33: 23 | K33: 1 | L33: 12
A34: Mixed Use (Commercial / Residential) | B34: 87339.281 | C34: 0 | D34: 575162.95 | E34: 0 | G34: 0 | H34: 104340.68 | I34: 749841.52 | J34: 20 | K34: 4 | L34: 9
A35: Residential | B35: 2261770 | C35: 0 | D35: 1023687 | E35: 0 | F35: 44765.4 | G35: 0 | H35: 2441715.1 | I35: 5547227 | J35: 988 | K35: 74 | L35: 237
A36: Street and Outdoor area Lighting | C36: 0 | E36: 0 | G36: 0 | H36: 188559.06 | J36: 54 | K36: 2 | L36: 25
A37: Telecommunications | B37: 487846.46 | C37: 0 | D37: 20779.073 | E37: 0 | G37: 0 | H37: 147300.77 | I37: 996472 | J37: 152 | K37: 3 | L37: 21
A38: Temporary Services | B38: 6689.6737 | C38: 0 | D38: 7996.7398 | E38: 0 | G38: 0 | H38: 16634.336 | I38: 21376.087 | K38: 3
A40: 45017
A41: Customer Class | B41: Total Discounts (Non-Exempted Projects) | C41: Total Discounts (Exempted projects) | D41: Total Allowances (Non-Exempted Projects) | E41: Total Allowances (Exempted projects) | F41: Total Refund Payments Provided to Builders (Non-Exempted Projects) | G41: Total Refund Payments Provided to Builders (Exempted projects) | H41: Total Estimated Non-Refundable | I41: Total Estimated Refundable | J41: Total Electric Line Extension Requests Received (Applications) | K41: Total Electric Line Extensions Energized | L41: Total Electric Line Extension Applications for Applicant Install
A42: Agency (City, County, Caltrans) | B42: 26649.811 | C42: 0 | D42: 64117.974 | E42: 0 | G42: 0 | H42: 45497.278 | I42: 117417.6 | J42: 45 | K42: 2 | L42: 20
...

Sheet Mixed Fuel Upgrades Existing
A1: Category: Upgrades to Existing Facilities
A2: Dates to Pull: January 01, 2023 - December 31, 2023
A3: Due Date: May 01, 2024
A4: 44927 | B4: Item 9 | C4: Item 12 | D4: Item 7 | E4: Item 10 | F4: Item 8 | G4: Item 11 | H4: Item 3 | I4: Item 2 | J4: Item 1 | K4: Item 4 | L4: Item 14
A5: Customer Class | B5: Total Discounts (Non-Exempted Projects) | C5: Total Discounts (Exempted projects) | D5: Total Allowances (Non-Exempted Projects) | E5: Total Allowances (Exempted projects) | F5: Total Refund Payments Provided to Builders (Non-Exempted Projects) | G5: Total Refund Payments Provided to Builders (Exempted projects) | H5: Total Estimated Non-Refundable | I5: Total Estimated Refundable | J5: Total Electric Line Extension Requests Received (Applications) | K5: Total Electric Line Extensions Energized | L5: Total Electric Line Extension Applications for Applicant Install
A6: Agency (City, County, Caltrans) | B6: 0 | C6: 0 | D6: 369.8672 | E6: 0 | G6: 0 | H6: 125 | I6: 369.8672
A7: Agricultural | C7: 0 | E7: 0 | G7: 0
A8: Commercial | C8: 0 | E8: 0 | G8: 0 | J8: 2 | L8: 2
A9: Industrial | C9: 0 | E9: 0 | G9: 0
A10: Mixed Use (Commercial / Residential) | C10: 0 | E10: 0 | G10: 0
A11: Residential | B11: 2989.857 | C11: 0 | D11: 0 | E11: 0 | G11: 0 | H11: 105881.13 | I11: 5979.714 | J11: 4 | K11: 15 | L11: 3
A12: Street and Outdoor area Lighting | C12: 0 | E12: 0 | G12: 0
A13: Telecommunications | C13: 0 | E13: 0 | G13: 0
A14: Temporary Services | C14: 0 | E14: 0 | G14: 0
A16: 45345
A17: Customer Class | B17: Total Discounts (Non-Exempted Projects) | C17: Total Discounts (Exempted projects) | D17: Total Allowances (Non-Exempted Projects) | E17: Total Allowances (Exempted projects) | F17: Total Refund Payments Provided to Builders (Non-Exempted Projects) | G17: Total Refund Payments Provided to Builders (Exempted projects) | H17: Total Estimated Non-Refundable | I17: Total Estimated Refundable | J17: Total Electric Line Extension Requests Received (Applications) | K17: Total Electric Line Extensions Energized | L17: Total Electric Line Extension Applications for Applicant Install
A18: Agency (City, County, Caltrans) | C18: 0 | E18: 0 | G18: 0
A19: Agricultural | C19: 0 | E19: 0 | G19: 0
A20: Commercial | B20: 3244.8216 | C20: 0 | D20: 181794.98 | E20: 0 | G20: 0 | H20: 8303.7512 | I20: 188284.63 | J20: 2 | K20: 2 | L20: 2
A21: Industrial | C21: 0 | E21: 0 | G21: 0
A22: Mixed Use (Commercial / Residential) | C22: 0 | E22: 0 | G22: 0
A23: Residential | B23: 19340.348 | C23: 0 | D23: 13076.966 | E23: 0 | G23: 0 | H23: 128386.75 | I23: 51757.662 | J23: 9 | K23: 13 | L23: 4
A24: Street and Outdoor area Lighting | C24: 0 | E24: 0 | G24: 0
A25: Telecommunications | C25: 0 | E25: 0 | G25: 0
A26: Temporary Services | C26: 0 | E26: 0 | G26: 0
A28: 44986
A29: Customer Class | B29: Total Discounts (Non-Exempted Projects) | C29: Total Discounts (Exempted projects) | D29: Total Allowances (Non-Exempted Projects) | E29: Total Allowances (Exempted projects) | F29: Total Refund Payments Provided to Builders (Non-Exempted Projects) | G29: Total Refund Payments Provided to Builders (Exempted projects) | H29: Total Estimated Non-Refundable | I29: Total Estimated Refundable | J29: Total Electric Line Extension Requests Received (Applications) | K29: Total Electric Line Extensions Energized | L29: Total Electric Line Extension Applications for Applicant Install
A30: Agency (City, County, Caltrans) | C30: 0 | E30: 0 | G30: 0
A31: Agricultural | C31: 0 | E31: 0 | G31: 0
A32: Commercial | B32: 0 | C32: 0 | D32: 109047.15 | E32: 0 | G32: 0 | H32: 47293.963 | I32: 109047.15 | K32: 1
A33: Industrial | B33: 17075.544 | C33: 0 | D33: 163703.52 | E33: 0 | G33: 0 | H33: 7830.15 | I33: 197854.61
A34: Mixed Use (Commercial / Residential) | B34: 1513.3412 | C34: 0 | D34: 303371.69 | E34: 0 | G34: 0 | H34: 53870.676 | I34: 306398.37
A35: Residential | B35: 0 | C35: 0 | D35: 0 | E35: 0 | G35: 0 | H35: 47945.06 | I35: 0 | J35: 8 | K35: 12 | L35: 4
A36: Street and Outdoor area Lighting | C36: 0 | E36: 0 | G36: 0
A37: Telecommunications | C37: 0 | E37: 0 | G37: 0
A38: Temporary Services | C38: 0 | E38: 0 | G38: 0
A40: 45017
A41: Customer Class | B41: Total Discounts (Non-Exempted Projects) | C41: Total Discounts (Exempted projects) | D41: Total Allowances (Non-Exempted Projects) | E41: Total Allowances (Exempted projects) | F41: Total Refund Payments Provided to Builders (Non-Exempted Projects) | G41: Total Refund Payments Provided to Builders (Exempted projects) | H41: Total Estimated Non-Refundable | I41: Total Estimated Refundable | J41: Total Electric Line Extension Requests Received (Applications) | K41: Total Electric Line Extensions Energized | L41: Total Electric Line Extension Applications for Applicant Install
A42: Agency (City, County, Caltrans) | B42: 18795.138 | C42: 0 | D42: 67959.057 | E42: 0 | G42: 0 | H42: 11841.211 | I42: 105549.33
A43: Agricultural | C43: 0 | E43: 0 | G43: 0
...

Sheet All Electric Upgrades Existing
A1: Category: Upgrades to Existing Facilities
A2: Dates to Pull: January 01, 2023 - December 31, 2023
A3: Due Date: May 01, 2024
A4: 44927 | B4: Item 9 | C4: Item 12 | D4: Item 7 | E4: Item 10 | F4: Item 8 | G4: Item 11 | H4: Item 3 | I4: Item 2 | J4: Item 1 | K4: Item 4 | L4: Item 14
A5: Customer Class | B5: Total Discounts (Non-Exempted Projects) | C5: Total Discounts (Exempted projects) | D5: Total Allowances (Non-Exempted Projects) | E5: Total Allowances (Exempted projects) | F5: Total Refund Payments Provided to Builders (Non-Exempted Projects) | G5: Total Refund Payments Provided to Builders (Exempted projects) | H5: Total Estimated Non-Refundable | I5: Total Estimated Refundable | J5: Total Electric Line Extension Requests Received (Applications) | K5: Total Electric Line Extensions Energized | L5: Total Electric Line Extension Applications for Applicant Install
A6: Agency (City, County, Caltrans) | B6: 1698.9428 | C6: 0 | D6: 84530.353 | E6: 0 | G6: 0 | H6: 10127.013 | I6: 87928.239 | J6: 5 | K6: 2 | L6: 3
A7: Agricultural | B7: 62130.892 | C7: 0 | D7: 738253.83 | E7: 0 | F7: 2115.22 | G7: 0 | H7: 25090.684 | I7: 862515.62 | J7: 6 | K7: 9 | L7: 3
A8: Commercial | B8: 470418.43 | C8: 0 | D8: 479026.38 | E8: 0 | F8: 28923.07 | G8: 0 | H8: 162489.06 | I8: 1419863.2 | J8: 30 | K8: 17 | L8: 17
A9: Industrial | B9: 1820.6324 | C9: 0 | D9: 18488.098 | E9: 0 | G9: 0 | H9: 125 | I9: 22129.362 | J9: 5 | L9: 5
A10: Mixed Use (Commercial / Residential) | B10: 126788.15 | C10: 0 | D10: 56679.764 | E10: 0 | F10: 782.71 | G10: 0 | H10: 22809.068 | I10: 310256.07 | J10: 3 | K10: 7 | L10: 2
A11: Residential | B11: 122971.2 | C11: 0 | D11: 32074.388 | E11: 0 | G11: 0 | H11: 931829.06 | I11: 278016.79 | J11: 568 | K11: 119 | L11: 465
A12: Street and Outdoor area Lighting | C12: 0 | E12: 0 | G12: 0 | H12: 10501.61 | J12: 1 | L12: 1
A13: Telecommunications | B13: 3265.666 | C13: 0 | D13: 712.74797 | E13: 0 | G13: 0 | H13: 2615.6268 | I13: 7244.08 | J13: 15 | L13: 5
A14: Temporary Services | C14: 0 | E14: 0 | G14: 0
A16: 45345
A17: Customer Class | B17: Total Discounts (Non-Exempted Projects) | C17: Total Discounts (Exempted projects) | D17: Total Allowances (Non-Exempted Projects) | E17: Total Allowances (Exempted projects) | F17: Total Refund Payments Provided to Builders (Non-Exempted Projects) | G17: Total Refund Payments Provided to Builders (Exempted projects) | H17: Total Estimated Non-Refundable | I17: Total Estimated Refundable | J17: Total Electric Line Extension Requests Received (Applications) | K17: Total Electric Line Extensions Energized | L17: Total Electric Line Extension Applications for Applicant Install
A18: Agency (City, County, Caltrans) | B18: 83953.139 | C18: 0 | D18: 187424.98 | E18: 0 | G18: 0 | H18: 41764.142 | I18: 355331.26 | J18: 4 | K18: 1 | L18: 3
A19: Agricultural | B19: 89985.722 | C19: 0 | D19: 616700.19 | E19: 0 | F19: 5095.28 | G19: 0 | H19: 29860.061 | I19: 796671.63 | J19: 9 | K19: 27 | L19: 4
A20: Commercial | B20: 225490.52 | C20: 0 | D20: 389280.54 | E20: 0 | F20: 71397.45 | G20: 0 | H20: 90459.508 | I20: 840261.58 | J20: 29 | K20: 19 | L20: 10
A21: Industrial | C21: 0 | E21: 0 | G21: 0 | J21: 2 | K21: 1
A22: Mixed Use (Commercial / Residential) | B22: 40541.205 | C22: 0 | D22: 191626.72 | E22: 0 | F22: 1505.05 | G22: 0 | H22: 45645.162 | I22: 272709.13 | J22: 6 | K22: 8 | L22: 2
A23: Residential | B23: 89634.617 | C23: 0 | D23: 67976.041 | E23: 0 | G23: 0 | H23: 945975.94 | I23: 247245.27 | J23: 576 | K23: 205 | L23: 509
A24: Street and Outdoor area Lighting | B24: 10898.381 | C24: 0 | D24: 712.74797 | E24: 0 | G24: 0 | H24: 46326.829 | I24: 22509.509 | J24: 2
A25: Telecommunications | B25: 334.29982 | C25: 0 | D25: 712.74797 | E25: 0 | G25: 0 | H25: 125 | I25: 1381.3476 | J25: 17
A26: Temporary Services | C26: 0 | E26: 0 | G26: 0
A28: 44986
A29: Customer Class | B29: Total Discounts (Non-Exempted Projects) | C29: Total Discounts (Exempted projects) | D29: Total Allowances (Non-Exempted Projects) | E29: Total Allowances (Exempted projects) | F29: Total Refund Payments Provided to Builders (Non-Exempted Projects) | G29: Total Refund Payments Provided to Builders (Exempted projects) | H29: Total Estimated Non-Refundable | I29: Total Estimated Refundable | J29: Total Electric Line Extension Requests Received (Applications) | K29: Total Electric Line Extensions Energized | L29: Total Electric Line Extension Applications for Applicant Install
A30: Agency (City, County, Caltrans) | B30: 13537.163 | C30: 0 | D30: 2130.1789 | E30: 0 | G30: 0 | H30: 3276.6144 | I30: 29204.505 | J30: 5 | K30: 2 | L30: 2
A31: Agricultural | B31: 130402.22 | C31: 0 | D31: 902373.12 | E31: 0 | F31: 19070.69 | G31: 0 | H31: 26675.178 | I31: 1163177.6 | J31: 10 | K31: 13 | L31: 5
A32: Commercial | B32: 1197851.9 | C32: 0 | D32: 1468765.7 | E32: 0 | G32: 0 | H32: 260941.15 | I32: 3864469.4 | J32: 37 | K32: 8 | L32: 22
A33: Industrial | B33: 51018.941 | C33: 0 | D33: 57381.181 | E33: 0 | G33: 0 | H33: 5930.4484 | I33: 159419.06 | J33: 3 | L33: 2
A34: Mixed Use (Commercial / Residential) | B34: 32617.736 | C34: 0 | D34: 80753.647 | E34: 0 | F34: 17003.3 | G34: 0 | H34: 7658.1036 | I34: 145989.12 | J34: 10 | K34: 3 | L34: 4
A35: Residential | B35: 31234.281 | C35: 0 | D35: 14181.405 | E35: 0 | G35: 0 | H35: 1000458.8 | I35: 76649.968 | J35: 903 | K35: 124 | L35: 744
A36: Street and Outdoor area Lighting | B36: 0 | C36: 0 | D36: 11910.932 | E36: 0 | G36: 0 | H36: 6819.6532 | I36: 11910.932 | J36: 3
A37: Telecommunications | B37: 100748.34 | C37: 0 | D37: 3563.7398 | E37: 0 | G37: 0 | H37: 15437.119 | I37: 205060.41 | J37: 15 | K37: 1 | L37: 4
A38: Temporary Services | C38: 0 | E38: 0 | G38: 0
A40: 45017
A41: Customer Class | B41: Total Discounts (Non-Exempted Projects) | C41: Total Discounts (Exempted projects) | D41: Total Allowances (Non-Exempted Projects) | E41: Total Allowances (Exempted projects) | F41: Total Refund Payments Provided to Builders (Non-Exempted Projects) | G41: Total Refund Payments Provided to Builders (Exempted projects) | H41: Total Estimated Non-Refundable | I41: Total Estimated Refundable | J41: Total Electric Line Extension Requests Received (Applications) | K41: Total Electric Line Extensions Energized | L41: Total Electric Line Extension Applications for Applicant Install
A42: Agency (City, County, Caltrans) | B42: 119076.22 | C42: 0 | D42: 90506.306 | E42: 0 | G42: 0 | H42: 58068.019 | I42: 328658.75 | J42: 1 | K42: 4 | L42: 1
A43: Agricultural | B43: 103335.31 | C43: 0 | D43: 579211.03 | E43: 0 | G43: 0 | H43: 13015.786 | I43: 785881.64 | J43: 5 | K43: 43 | L43: 2
...
