Workbook

Sheet Sheet1
A1: Category: MIXED FUEL NEW CONSTRUCTION
A2: Dates to Pull: January 01, 2024 ‐ December 31, 2024
A3: Due Date: May 01, 2025
A4: *Customer classes vary between IOU's
A7: January | B7: Item 9 | C7: item 12 | D7: Item 7 | E7: Item 10 | F7: Item 8 | G7: Item 11 | H7: Item 3 | I7: Item 2 | J7: Item 1 | K7: Item 4 | L7: Item 14
A8: Customer Class | B8: Total Discounts (Non‐Exempted Projects) | C8: Total Discounts (Exempted projects) | D8: Total Allowances (Non‐Exempted Projects) | E8: Total Allowances (Exempted projects) | F8: Total Refund Payments Provided to Builders (Non‐Exempted Projects) | G8: Total Refund Payments Provided to Builders (Exempted projects) | H8: Total Estimated Non‐Refundable | I8: Total Estimated Refundable | J8: Total Electric Line Extension Requests received (applications) | K8: Total Electric Line Extensions Energized | L8: Total Electric Line Extension Applications for applicant install
A10: Agency (City, County, Caltrans) | B10: 34947 | C10: 0 | D10: 23785 | E10: 0 | F10: 0 | G10: 0 | H10: 8530 | I10: 93678 | J10: 1
A11: Agricultural | B11: 2352 | C11: 0 | D11: 0 | E11: 0 | F11: 0 | G11: 0 | H11: 1564 | I11: 4705 | J11: 4 | L11: 1
A12: Commercial | B12: 2154069 | C12: 0 | D12: 2223555 | E12: 0 | F12: 13735 | G12: 0 | H12: 534142 | I12: 6531693 | J12: 30 | K12: 20 | L12: 9
A13: Industrial | B13: 0 | C13: 0 | D13: 0 | E13: 0 | F13: 0 | G13: 0 | H13: 0 | I13: 0 | J13: 6 | K13: 1 | L13: 2
A14: Mixed Use (Commercial / Residential) | B14: 65787 | C14: 0 | D14: 45715 | E14: 0 | F14: 6532 | G14: 0 | H14: 22614 | I14: 177289 | J14: 3 | K14: 3 | L14: 1
A15: Residential | B15: 6261218 | C15: 0 | D15: 3839388 | E15: 0 | F15: 49132 | G15: 0 | H15: 2935514 | I15: 16685228 | J15: 218 | K15: 86 | L15: 49
A16: Street and Outdoor area Lighting | B16: 0 | C16: 0 | D16: 0 | E16: 0 | F16: 0 | G16: 0 | H16: 0 | I16: 0
A17: Telecommunications | B17: 0 | C17: 0 | D17: 0 | E17: 0 | F17: 0 | G17: 0 | H17: 0 | I17: 0
A18: Temporary Services | B18: 0 | C18: 0 | D18: 0 | E18: 0 | F18: 0 | G18: 0 | H18: 0 | I18: 0
A20: February | B20: Item 9 | C20: item 12 | D20: Item 7 | E20: Item 10 | F20: Item 8 | G20: Item 11 | H20: Item 3 | I20: Item 2 | J20: Item 1 | K20: Item 4 | L20: Item 14
A21: Customer Class | B21: Total Discounts (Non‐Exempted Projects) | C21: Total Discounts (Exempted projects) | D21: Total Allowances (Non‐Exempted Projects) | E21: Total Allowances (Exempted projects) | F21: Total Refund Payments Provided to Builders (Non‐Exempted Projects) | G21: Total Refund Payments Provided to Builders (Exempted projects) | H21: Total Estimated Non‐Refundable | I21: Total Estimated Refundable | J21: Total Electric Line Extension Requests received (applications) | K21: Total Electric Line Extensions Energized | L21: Total Electric Line Extension Applications for applicant install
A23: Agency (City, County, Caltrans) | B23: 0 | C23: 0 | D23: 0 | E23: 0 | F23: 0 | H23: 0 | I23: 0
A24: Agricultural | B24: 0 | C24: 0 | D24: 0 | E24: 0 | F24: 0 | H24: 0 | I24: 0 | J24: 1
A25: Commercial | B25: 2496365 | C25: 0 | D25: 1871907 | E25: 0 | F25: 64392 | H25: 346491 | I25: 6864637 | J25: 29 | K25: 19 | L25: 9
A26: Industrial | B26: 0 | C26: 0 | D26: 301918 | E26: 0 | F26: 0 | H26: 6843 | I26: 301918 | J26: 2 | L26: 2
A27: Mixed Use (Commercial / Residential) | B27: 71856 | C27: 0 | D27: 528537 | E27: 0 | F27: 2411 | H27: 68704 | I27: 672249 | J27: 5 | K27: 4 | L27: 4
A28: Residential | B28: 2968529 | C28: 0 | D28: 1458026 | E28: 0 | F28: 371659 | H28: 2189194 | I28: 7912520 | J28: 211 | K28: 78 | L28: 35
A29: Street and Outdoor area Lighting | B29: 0 | C29: 0 | D29: 0 | E29: 0 | F29: 0 | H29: 0 | I29: 0
A30: Telecommunications | B30: 0 | C30: 0 | D30: 0 | E30: 0 | F30: 0 | H30: 0 | I30: 0
A31: Temporary Services | B31: 0 | C31: 0 | D31: 0 | E31: 0 | F31: 0 | H31: 0 | I31: 0
A33: March | B33: Item 9 | C33: item 12 | D33: Item 7 | E33: Item 10 | F33: Item 8 | G33: Item 11 | H33: Item 3 | I33: Item 2 | J33: Item 1 | K33: Item 4 | L33: Item 14
A34: Customer Class | B34: Total Discounts (Non‐Exempted Projects) | C34: Total Discounts (Exempted projects) | D34: Total Allowances (Non‐Exempted Projects) | E34: Total Allowances (Exempted projects) | F34: Total Refund Payments Provided to Builders (Non‐Exempted Projects) | G34: Total Refund Payments Provided to Builders (Exempted projects) | H34: Total Estimated Non‐Refundable | I34: Total Estimated Refundable | J34: Total Electric Line Extension Requests received (applications) | K34: Total Electric Line Extensions Energized | L34: Total Electric Line Extension Applications for applicant install
A36: Agency (City, County, Caltrans) | B36: 0 | C36: 0 | D36: 0 | E36: 0 | F36: 0 | H36: 0 | I36: 0 | J36: 2
A37: Agricultural | B37: 0 | C37: 0 | D37: 0 | E37: 0 | F37: 0 | H37: 0 | I37: 0 | J37: 1
A38: Commercial | B38: 1197197 | C38: 0 | D38: 1118740 | E38: 0 | F38: 0 | H38: 303370 | I38: 3513135 | J38: 37 | K38: 23 | L38: 18
A39: Industrial | B39: 86196 | C39: 0 | D39: 46448 | E39: 0 | F39: 0 | H39: 26380 | I39: 218839 | J39: 3 | L39: 1
A40: Mixed Use (Commercial / Residential) | B40: 0 | C40: 0 | D40: 159042 | E40: 0 | F40: 3204.09 | H40: 22940 | I40: 159042 | J40: 2 | K40: 2 | L40: 1
A41: Residential | B41: 7490314 | C41: 0 | D41: 4481781 | E41: 0 | F41: 223345 | H41: 3509612 | I41: 19741962 | J41: 221 | K41: 101 | L41: 51
A42: Street and Outdoor area Lighting | B42: 0 | C42: 0 | D42: 0 | E42: 0 | F42: 0 | H42: 0 | I42: 0
A43: Telecommunications | B43: 0 | C43: 0 | D43: 0 | E43: 0 | F43: 0 | H43: 0 | I43: 0
A44: Temporary Services | B44: 0 | C44: 0 | D44: 0 | E44: 0 | F44: 0 | H44: 0 | I44: 0
A46: April | B46: Item 9 | C46: item 12 | D46: Item 7 | E46: Item 10 | F46: Item 8 | G46: Item 11 | H46: Item 3 | I46: Item 2 | J46: Item 1 | K46: Item 4 | L46: Item 14
A47: Customer Class | B47: Total Discounts (Non‐Exempted Projects) | C47: Total Discounts (Exempted projects) | D47: Total Allowances (Non‐Exempted Projects) | E47: Total Allowances (Exempted projects) | F47: Total Refund Payments Provided to Builders (Non‐Exempted Projects) | G47: Total Refund Payments Provided to Builders (Exempted projects) | H47: Total Estimated Non‐Refundable | I47: Total Estimated Refundable | J47: Total Electric Line Extension Requests received (applications) | K47: Total Electric Line Extensions Energized | L47: Total Electric Line Extension Applications for applicant install
A49: Agency (City, County, Caltrans) | B49: 189016 | C49: 0 | D49: 852 | E49: 0 | F49: 0 | H49: 36299 | I49: 378883 | J49: 1
...

Sheet validate entries (rwy2)
A1: Category: MIXED FUEL NEW CONSTRUCTION
A2: Dates to Pull: January 01, 2024 ‐ December 31, 2024
A3: Due Date: May 01, 2025
A4: *Customer classes vary between IOU's
B7: Item 9 | C7: item 12 | D7: Item 7 | E7: Item 10 | F7: Item 8 | G7: Item 11 | H7: Item 3 | I7: Item 2 | J7: Item 1 | K7: Item 4 | L7: Item 14
A8: Customer Class | B8: Total Discounts (Non‐Exempted Projects) | C8: Total Discounts (Exempted projects) | D8: Total Allowances (Non‐Exempted Projects) | E8: Total Allowances (Exempted projects) | F8: Total Refund Payments Provided to Builders (Non‐Exempted Projects) | G8: Total Refund Payments Provided to Builders (Exempted projects) | H8: Total Estimated Non‐Refundable | I8: Total Estimated Refundable | J8: Total Electric Line Extension Requests received (applications) | K8: Total Electric Line Extensions Energized | L8: Total Electric Line Extension Applications for applicant install
A10: Agency (City, County, Caltrans) | J10: =SUM(Sheet1!J10,Sheet1!J23,Sheet1!J36,Sheet1!J49,Sheet1!J62,Sheet1!J75,Sheet1!J88,Sheet1!J101,Sheet1!J114,Sheet1!J127,Sheet1!J140,Sheet1!J153) -> 15 | K10: =SUM(Sheet1!K10,Sheet1!K23,Sheet1!K36,Sheet1!K49,Sheet1!K62,Sheet1!K75,Sheet1!K88,Sheet1!K101,Sheet1!K114,Sheet1!K127,Sheet1!K140,Sheet1!K153) -> 3 | L10: =SUM(Sheet1!L10,Sheet1!L23,Sheet1!L36,Sheet1!L49,Sheet1!L62,Sheet1!L75,Sheet1!L88,Sheet1!L101,Sheet1!L114,Sheet1!L127,Sheet1!L140,Sheet1!L153) -> 6
A11: Agricultural | J11: =SUM(Sheet1!J11,Sheet1!J24,Sheet1!J37,Sheet1!J50,Sheet1!J63,Sheet1!J76,Sheet1!J89,Sheet1!J102,Sheet1!J115,Sheet1!J128,Sheet1!J141,Sheet1!J154) -> 9 | K11: =SUM(Sheet1!K11,Sheet1!K24,Sheet1!K37,Sheet1!K50,Sheet1!K63,Sheet1!K76,Sheet1!K89,Sheet1!K102,Sheet1!K115,Sheet1!K128,Sheet1!K141,Sheet1!K154) -> 3 | L11: =SUM(Sheet1!L11,Sheet1!L24,Sheet1!L37,Sheet1!L50,Sheet1!L63,Sheet1!L76,Sheet1!L89,Sheet1!L102,Sheet1!L115,Sheet1!L128,Sheet1!L141,Sheet1!L154) -> 1
A12: Commercial | J12: =SUM(Sheet1!J12,Sheet1!J25,Sheet1!J38,Sheet1!J51,Sheet1!J64,Sheet1!J77,Sheet1!J90,Sheet1!J103,Sheet1!J116,Sheet1!J129,Sheet1!J142,Sheet1!J155) -> 365 | K12: =SUM(Sheet1!K12,Sheet1!K25,Sheet1!K38,Sheet1!K51,Sheet1!K64,Sheet1!K77,Sheet1!K90,Sheet1!K103,Sheet1!K116,Sheet1!K129,Sheet1!K142,Sheet1!K155) -> 270 | L12: =SUM(Sheet1!L12,Sheet1!L25,Sheet1!L38,Sheet1!L51,Sheet1!L64,Sheet1!L77,Sheet1!L90,Sheet1!L103,Sheet1!L116,Sheet1!L129,Sheet1!L142,Sheet1!L155) -> 134
A13: Industrial | J13: =SUM(Sheet1!J13,Sheet1!J26,Sheet1!J39,Sheet1!J52,Sheet1!J65,Sheet1!J78,Sheet1!J91,Sheet1!J104,Sheet1!J117,Sheet1!J130,Sheet1!J143,Sheet1!J156) -> 23 | K13: =SUM(Sheet1!K13,Sheet1!K26,Sheet1!K39,Sheet1!K52,Sheet1!K65,Sheet1!K78,Sheet1!K91,Sheet1!K104,Sheet1!K117,Sheet1!K130,Sheet1!K143,Sheet1!K156) -> 7 | L13: =SUM(Sheet1!L13,Sheet1!L26,Sheet1!L39,Sheet1!L52,Sheet1!L65,Sheet1!L78,Sheet1!L91,Sheet1!L104,Sheet1!L117,Sheet1!L130,Sheet1!L143,Sheet1!L156) -> 12
A14: Mixed Use (Commercial / Residential) | J14: =SUM(Sheet1!J14,Sheet1!J27,Sheet1!J40,Sheet1!J53,Sheet1!J66,Sheet1!J79,Sheet1!J92,Sheet1!J105,Sheet1!J118,Sheet1!J131,Sheet1!J144,Sheet1!J157) -> 71 | K14: =SUM(Sheet1!K14,Sheet1!K27,Sheet1!K40,Sheet1!K53,Sheet1!K66,Sheet1!K79,Sheet1!K92,Sheet1!K105,Sheet1!K118,Sheet1!K131,Sheet1!K144,Sheet1!K157) -> 38 | L14: =SUM(Sheet1!L14,Sheet1!L27,Sheet1!L40,Sheet1!L53,Sheet1!L66,Sheet1!L79,Sheet1!L92,Sheet1!L105,Sheet1!L118,Sheet1!L131,Sheet1!L144,Sheet1!L157) -> 33
A15: Residential | J15: =SUM(Sheet1!J15,Sheet1!J28,Sheet1!J41,Sheet1!J54,Sheet1!J67,Sheet1!J80,Sheet1!J93,Sheet1!J106,Sheet1!J119,Sheet1!J132,Sheet1!J145,Sheet1!J158) -> 2630 | K15: =SUM(Sheet1!K15,Sheet1!K28,Sheet1!K41,Sheet1!K54,Sheet1!K67,Sheet1!K80,Sheet1!K93,Sheet1!K106,Sheet1!K119,Sheet1!K132,Sheet1!K145,Sheet1!K158) -> 1153 | L15: =SUM(Sheet1!L15,Sheet1!L28,Sheet1!L41,Sheet1!L54,Sheet1!L67,Sheet1!L80,Sheet1!L93,Sheet1!L106,Sheet1!L119,Sheet1!L132,Sheet1!L145,Sheet1!L158) -> 572
A16: Street and Outdoor area Lighting | J16: =SUM(Sheet1!J16,Sheet1!J29,Sheet1!J42,Sheet1!J55,Sheet1!J68,Sheet1!J81,Sheet1!J94,Sheet1!J107,Sheet1!J120,Sheet1!J133,Sheet1!J146,Sheet1!J159) -> 0 | K16: =SUM(Sheet1!K16,Sheet1!K29,Sheet1!K42,Sheet1!K55,Sheet1!K68,Sheet1!K81,Sheet1!K94,Sheet1!K107,Sheet1!K120,Sheet1!K133,Sheet1!K146,Sheet1!K159) -> 0 | L16: =SUM(Sheet1!L16,Sheet1!L29,Sheet1!L42,Sheet1!L55,Sheet1!L68,Sheet1!L81,Sheet1!L94,Sheet1!L107,Sheet1!L120,Sheet1!L133,Sheet1!L146,Sheet1!L159) -> 0
A17: Telecommunications | J17: =SUM(Sheet1!J17,Sheet1!J30,Sheet1!J43,Sheet1!J56,Sheet1!J69,Sheet1!J82,Sheet1!J95,Sheet1!J108,Sheet1!J121,Sheet1!J134,Sheet1!J147,Sheet1!J160) -> 0 | K17: =SUM(Sheet1!K17,Sheet1!K30,Sheet1!K43,Sheet1!K56,Sheet1!K69,Sheet1!K82,Sheet1!K95,Sheet1!K108,Sheet1!K121,Sheet1!K134,Sheet1!K147,Sheet1!K160) -> 0 | L17: =SUM(Sheet1!L17,Sheet1!L30,Sheet1!L43,Sheet1!L56,Sheet1!L69,Sheet1!L82,Sheet1!L95,Sheet1!L108,Sheet1!L121,Sheet1!L134,Sheet1!L147,Sheet1!L160) -> 0
A18: Temporary Services | J18: =SUM(Sheet1!J18,Sheet1!J31,Sheet1!J44,Sheet1!J57,Sheet1!J70,Sheet1!J83,Sheet1!J96,Sheet1!J109,Sheet1!J122,Sheet1!J135,Sheet1!J148,Sheet1!J161) -> 0 | K18: =SUM(Sheet1!K18,Sheet1!K31,Sheet1!K44,Sheet1!K57,Sheet1!K70,Sheet1!K83,Sheet1!K96,Sheet1!K109,Sheet1!K122,Sheet1!K135,Sheet1!K148,Sheet1!K161) -> 2 | L18: =SUM(Sheet1!L18,Sheet1!L31,Sheet1!L44,Sheet1!L57,Sheet1!L70,Sheet1!L83,Sheet1!L96,Sheet1!L109,Sheet1!L122,Sheet1!L135,Sheet1!L148,Sheet1!L161) -> 0
A19: TOTAL | J19: =SUM(J10:J18) -> 3113 | K19: =SUM(K10:K18) -> 1476 | L19: =SUM(L10:L18) -> 758
A21: Category: Upgrades to Existing Facilities (All Electric)
A22: Dates to Pull: January 01, 2024 ‐ December 31, 2024
A23: Due Date: May 01, 2025
B25: Item 9 | C25: item 12 | D25: Item 7 | E25: Item 10 | F25: Item 8 | G25: Item 11 | H25: Item 3 | I25: Item 2 | J25: Item 1 | K25: Item 4 | L25: Item 14
A26: Customer Class | B26: Total Discounts (Non‐Exempted Projects) | C26: Total Discounts (Exempted projects) | D26: Total Allowances (Non‐Exempted Projects) | E26: Total Allowances (Exempted projects) | F26: Total Refund Payments Provided to Builders (Non‐Exempted Projects) | G26: Total Refund Payments Provided to Builders (Exempted projects) | H26: Total Estimated Non‐Refundable | I26: Total Estimated Refundable | J26: Total Electric Line Extension Requests received (applications) | K26: Total Electric Line Extensions Energized | L26: Total Electric Line Extension Applications for applicant install
A28: Agency (City, County, Caltrans) | J28: =SUM(Sheet1!J185,Sheet1!J198,Sheet1!J211,Sheet1!J224,Sheet1!J237,Sheet1!J250,Sheet1!J263,Sheet1!J276,Sheet1!J289,Sheet1!J302,Sheet1!J315,Sheet1!J328) -> 15 | K28: =SUM(Sheet1!K185,Sheet1!K198,Sheet1!K211,Sheet1!K224,Sheet1!K237,Sheet1!K250,Sheet1!K263,Sheet1!K276,Sheet1!K289,Sheet1!K302,Sheet1!K315,Sheet1!K328) -> 86 | L28: =SUM(Sheet1!L185,Sheet1!L198,Sheet1!L211,Sheet1!L224,Sheet1!L237,Sheet1!L250,Sheet1!L263,Sheet1!L276,Sheet1!L289,Sheet1!L302,Sheet1!L315,Sheet1!L328) -> 1
A29: Agricultural | J29: =SUM(Sheet1!J186,Sheet1!J199,Sheet1!J212,Sheet1!J225,Sheet1!J238,Sheet1!J251,Sheet1!J264,Sheet1!J277,Sheet1!J290,Sheet1!J303,Sheet1!J316,Sheet1!J329) -> 26 | K29: =SUM(Sheet1!K186,Sheet1!K199,Sheet1!K212,Sheet1!K225,Sheet1!K238,Sheet1!K251,Sheet1!K264,Sheet1!K277,Sheet1!K290,Sheet1!K303,Sheet1!K316,Sheet1!K329) -> 290 | L29: =SUM(Sheet1!L186,Sheet1!L199,Sheet1!L212,Sheet1!L225,Sheet1!L238,Sheet1!L251,Sheet1!L264,Sheet1!L277,Sheet1!L290,Sheet1!L303,Sheet1!L316,Sheet1!L329) -> 4
A30: Commercial | J30: =SUM(Sheet1!J187,Sheet1!J200,Sheet1!J213,Sheet1!J226,Sheet1!J239,Sheet1!J252,Sheet1!J265,Sheet1!J278,Sheet1!J291,Sheet1!J304,Sheet1!J317,Sheet1!J330) -> 160 | K30: =SUM(Sheet1!K187,Sheet1!K200,Sheet1!K213,Sheet1!K226,Sheet1!K239,Sheet1!K252,Sheet1!K265,Sheet1!K278,Sheet1!K291,Sheet1!K304,Sheet1!K317,Sheet1!K330) -> 298 | L30: =SUM(Sheet1!L187,Sheet1!L200,Sheet1!L213,Sheet1!L226,Sheet1!L239,Sheet1!L252,Sheet1!L265,Sheet1!L278,Sheet1!L291,Sheet1!L304,Sheet1!L317,Sheet1!L330) -> 27
A31: Industrial | J31: =SUM(Sheet1!J188,Sheet1!J201,Sheet1!J214,Sheet1!J227,Sheet1!J240,Sheet1!J253,Sheet1!J266,Sheet1!J279,Sheet1!J292,Sheet1!J305,Sheet1!J318,Sheet1!J331) -> 7 | K31: =SUM(Sheet1!K188,Sheet1!K201,Sheet1!K214,Sheet1!K227,Sheet1!K240,Sheet1!K253,Sheet1!K266,Sheet1!K279,Sheet1!K292,Sheet1!K305,Sheet1!K318,Sheet1!K331) -> 19 | L31: =SUM(Sheet1!L188,Sheet1!L201,Sheet1!L214,Sheet1!L227,Sheet1!L240,Sheet1!L253,Sheet1!L266,Sheet1!L279,Sheet1!L292,Sheet1!L305,Sheet1!L318,Sheet1!L331) -> 6
A32: Mixed Use (Commercial / Residential) | J32: =SUM(Sheet1!J189,Sheet1!J202,Sheet1!J215,Sheet1!J228,Sheet1!J241,Sheet1!J254,Sheet1!J267,Sheet1!J280,Sheet1!J293,Sheet1!J306,Sheet1!J319,Sheet1!J332) -> 107 | K32: =SUM(Sheet1!K189,Sheet1!K202,Sheet1!K215,Sheet1!K228,Sheet1!K241,Sheet1!K254,Sheet1!K267,Sheet1!K280,Sheet1!K293,Sheet1!K306,Sheet1!K319,Sheet1!K332) -> 55 | L32: =SUM(Sheet1!L189,Sheet1!L202,Sheet1!L215,Sheet1!L228,Sheet1!L241,Sheet1!L254,Sheet1!L267,Sheet1!L280,Sheet1!L293,Sheet1!L306,Sheet1!L319,Sheet1!L332) -> 25
A33: Residential | J33: =SUM(Sheet1!J190,Sheet1!J203,Sheet1!J216,Sheet1!J229,Sheet1!J242,Sheet1!J255,Sheet1!J268,Sheet1!J281,Sheet1!J294,Sheet1!J307,Sheet1!J320,Sheet1!J333) -> 373 | K33: =SUM(Sheet1!K190,Sheet1!K203,Sheet1!K216,Sheet1!K229,Sheet1!K242,Sheet1!K255,Sheet1!K268,Sheet1!K281,Sheet1!K294,Sheet1!K307,Sheet1!K320,Sheet1!K333) -> 4928 | L33: =SUM(Sheet1!L190,Sheet1!L203,Sheet1!L216,Sheet1!L229,Sheet1!L242,Sheet1!L255,Sheet1!L268,Sheet1!L281,Sheet1!L294,Sheet1!L307,Sheet1!L320,Sheet1!L333) -> 121
A34: Street and Outdoor area Lighting | J34: =SUM(Sheet1!J191,Sheet1!J204,Sheet1!J217,Sheet1!J230,Sheet1!J243,Sheet1!J256,Sheet1!J269,Sheet1!J282,Sheet1!J295,Sheet1!J308,Sheet1!J321,Sheet1!J334) -> 16 | K34: =SUM(Sheet1!K191,Sheet1!K204,Sheet1!K217,Sheet1!K230,Sheet1!K243,Sheet1!K256,Sheet1!K269,Sheet1!K282,Sheet1!K295,Sheet1!K308,Sheet1!K321,Sheet1!K334) -> 31 | L34: =SUM(Sheet1!L191,Sheet1!L204,Sheet1!L217,Sheet1!L230,Sheet1!L243,Sheet1!L256,Sheet1!L269,Sheet1!L282,Sheet1!L295,Sheet1!L308,Sheet1!L321,Sheet1!L334) -> 2
A35: Telecommunications | J35: =SUM(Sheet1!J192,Sheet1!J205,Sheet1!J218,Sheet1!J231,Sheet1!J244,Sheet1!J257,Sheet1!J270,Sheet1!J283,Sheet1!J296,Sheet1!J309,Sheet1!J322,Sheet1!J335) -> 241 | K35: =SUM(Sheet1!K192,Sheet1!K205,Sheet1!K218,Sheet1!K231,Sheet1!K244,Sheet1!K257,Sheet1!K270,Sheet1!K283,Sheet1!K296,Sheet1!K309,Sheet1!K322,Sheet1!K335) -> 23 | L35: =SUM(Sheet1!L192,Sheet1!L205,Sheet1!L218,Sheet1!L231,Sheet1!L244,Sheet1!L257,Sheet1!L270,Sheet1!L283,Sheet1!L296,Sheet1!L309,Sheet1!L322,Sheet1!L335) -> 27
A36: Temporary Services | J36: =SUM(Sheet1!J193,Sheet1!J206,Sheet1!J219,Sheet1!J232,Sheet1!J245,Sheet1!J258,Sheet1!J271,Sheet1!J284,Sheet1!J297,Sheet1!J310,Sheet1!J323,Sheet1!J336) -> 0 | K36: =SUM(Sheet1!K193,Sheet1!K206,Sheet1!K219,Sheet1!K232,Sheet1!K245,Sheet1!K258,Sheet1!K271,Sheet1!K284,Sheet1!K297,Sheet1!K310,Sheet1!K323,Sheet1!K336) -> 0 | L36: =SUM(Sheet1!L193,Sheet1!L206,Sheet1!L219,Sheet1!L232,Sheet1!L245,Sheet1!L258,Sheet1!L271,Sheet1!L284,Sheet1!L297,Sheet1!L310,Sheet1!L323,Sheet1!L336) -> 0
A37: TOTAL | J37: =SUM(J28:J36) -> 945 | K37: =SUM(K28:K36) -> 5730 | L37: =SUM(L28:L36) -> 213
A39: Category: Upgrades to Existing Facilities (Mixed Fuel)
A40: Dates to Pull: January 01, 2024 ‐ December 31, 2024
A41: Due Date: May 01, 2025
B43: Item 9 | C43: item 12 | D43: Item 7 | E43: Item 10 | F43: Item 8 | G43: Item 11 | H43: Item 3 | I43: Item 2 | J43: Item 1 | K43: Item 4 | L43: Item 14
A44: Customer Class | B44: Total Discounts (Non‐Exempted Projects) | C44: Total Discounts (Exempted projects) | D44: Total Allowances (Non‐Exempted Projects) | E44: Total Allowances (Exempted projects) | F44: Total Refund Payments Provided to Builders (Non‐Exempted Projects) | G44: Total Refund Payments Provided to Builders (Exempted projects) | H44: Total Estimated Non‐Refundable | I44: Total Estimated Refundable | J44: Total Electric Line Extension Requests received (applications) | K44: Total Electric Line Extensions Energized | L44: Total Electric Line Extension Applications for applicant install
A46: Agency (City, County, Caltrans) | J46: =SUM(Sheet1!J360,Sheet1!J373,Sheet1!J386,Sheet1!J399,Sheet1!J412,Sheet1!J425,Sheet1!J438,Sheet1!J451,Sheet1!J464,Sheet1!J477,Sheet1!J490,Sheet1!J503) -> 0 | K46: =SUM(Sheet1!K360,Sheet1!K373,Sheet1!K386,Sheet1!K399,Sheet1!K412,Sheet1!K425,Sheet1!K438,Sheet1!K451,Sheet1!K464,Sheet1!K477,Sheet1!K490,Sheet1!K503) -> 0 | L46: =SUM(Sheet1!L360,Sheet1!L373,Sheet1!L386,Sheet1!L399,Sheet1!L412,Sheet1!L425,Sheet1!L438,Sheet1!L451,Sheet1!L464,Sheet1!L477,Sheet1!L490,Sheet1!L503) -> 0
A47: Agricultural | J47: =SUM(Sheet1!J361,Sheet1!J374,Sheet1!J387,Sheet1!J400,Sheet1!J413,Sheet1!J426,Sheet1!J439,Sheet1!J452,Sheet1!J465,Sheet1!J478,Sheet1!J491,Sheet1!J504) -> 0 | K47: =SUM(Sheet1!K361,Sheet1!K374,Sheet1!K387,Sheet1!K400,Sheet1!K413,Sheet1!K426,Sheet1!K439,Sheet1!K452,Sheet1!K465,Sheet1!K478,Sheet1!K491,Sheet1!K504) -> 0 | L47: =SUM(Sheet1!L361,Sheet1!L374,Sheet1!L387,Sheet1!L400,Sheet1!L413,Sheet1!L426,Sheet1!L439,Sheet1!L452,Sheet1!L465,Sheet1!L478,Sheet1!L491,Sheet1!L504) -> 0
A48: Commercial | J48: =SUM(Sheet1!J362,Sheet1!J375,Sheet1!J388,Sheet1!J401,Sheet1!J414,Sheet1!J427,Sheet1!J440,Sheet1!J453,Sheet1!J466,Sheet1!J479,Sheet1!J492,Sheet1!J505) -> 1 | K48: =SUM(Sheet1!K362,Sheet1!K375,Sheet1!K388,Sheet1!K401,Sheet1!K414,Sheet1!K427,Sheet1!K440,Sheet1!K453,Sheet1!K466,Sheet1!K479,Sheet1!K492,Sheet1!K505) -> 27 | L48: =SUM(Sheet1!L362,Sheet1!L375,Sheet1!L388,Sheet1!L401,Sheet1!L414,Sheet1!L427,Sheet1!L440,Sheet1!L453,Sheet1!L466,Sheet1!L479,Sheet1!L492,Sheet1!L505) -> 1
A49: Industrial | J49: =SUM(Sheet1!J363,Sheet1!J376,Sheet1!J389,Sheet1!J402,Sheet1!J415,Sheet1!J428,Sheet1!J441,Sheet1!J454,Sheet1!J467,Sheet1!J480,Sheet1!J493,Sheet1!J506) -> 0 | K49: =SUM(Sheet1!K363,Sheet1!K376,Sheet1!K389,Sheet1!K402,Sheet1!K415,Sheet1!K428,Sheet1!K441,Sheet1!K454,Sheet1!K467,Sheet1!K480,Sheet1!K493,Sheet1!K506) -> 0 | L49: =SUM(Sheet1!L363,Sheet1!L376,Sheet1!L389,Sheet1!L402,Sheet1!L415,Sheet1!L428,Sheet1!L441,Sheet1!L454,Sheet1!L467,Sheet1!L480,Sheet1!L493,Sheet1!L506) -> 0
...
